Workbook
Name decompositie: Algemeen!$L$18:$L$37
Name aantal_componenten: Algemeen!$M$16:$M$37
Name Aantal_fregatten: Algemeen!$O$3
Name Aantal_ini_wal: Algemeen!$BW$16:$BW$37
Name Aantal_install.: Algemeen!$O$4
Name Aantal_max_wal: Algemeen!$BX$16:$BX$37
Name Aantal_res_boord: Algemeen!$BV$16:$BV$37
Name Aantal_res_wal: Algemeen!$BY$16:$BY$37
Name bestel_interval: Algemeen!$CW$16:$CW$37
Name besteltijd: Algemeen!$BS$16:$BS$37
Name CO_rep: Algemeen!$Z$16:$Z$37
Name CO_rep_verv_tijd: Algemeen!$BP$16:$BP$37
Name CO_verv: Algemeen!$AA$16:$AA$37
Name CO_zoektijd: Algemeen!$BO$16:$BO$37
Name cumm_ONB_aanvang: Algemeen!$EG$16:$EG$37
Name cumm_ONB_missie: Algemeen!$DX$16:$DX$37
Name doorlooptijd_invlieg: Algemeen!$DF$16:$DF$37
Name doorlooptijd_missie: Algemeen!$DJ$16:$DJ$37
Name doorlooptijd_missie_i: Algemeen!$DI$16:$DI$37
Name doorlooptijd_missie_met: Algemeen!$DE$16:$DE$37
Name doorlooptijd_missie_rep: Algemeen!$DD$16:$DD$37
Name doorlooptijd_missie_verv: Algemeen!$DH$16:$DH$37
Name doorlooptijd_missie_zonder: Algemeen!$DG$16:$DG$37
Name Doorlooptijd_transport: Algemeen!$DN$16:$DN$37
Name doorlooptijd_van_wal: Algemeen!$DM$16:$DM$37
Name doorlooptijd_wal: Algemeen!$DR$16:$DR$37
Name doorlooptijd_wal_i: Algemeen!$DQ$16:$DQ$37
Name doorlooptijd_wal_rep: Algemeen!$DL$16:$DL$37
Name doorlooptijd_wal_verv: Algemeen!$DP$16:$DP$37
Name doorlooptijd_wal_zonder: Algemeen!$DO$16:$DO$37
Name efAantFunc1: Algemeen!$L$13
Name efAantFunc2: Algemeen!$EU$12
Name einde_regels: Algemeen!$A$37
Name f_vast: Algemeen!$AW$16:$AW$37
Name functie_1: Algemeen!$EU$16:$EU$37
Name functie_10: Algemeen!$FD$16:$FD$37
Name functie_2: Algemeen!$EV$16:$EV$37
Name functie_3: Algemeen!$EW$16:$EW$37
Name functie_4: Algemeen!$EX$16:$EX$37
Name functie_5: Algemeen!$EY$16:$EY$37
Name functie_6: Algemeen!$EZ$16:$EZ$37
Name functie_7: Algemeen!$FA$16:$FA$37
Name functie_8: Algemeen!$FB$16:$FB$37
Name functie_9: Algemeen!$FC$16:$FC$37
Name gevolg_kosten: Algemeen!$BK$16:$BK$37
Name Gevolg_kosten_tradeoff: Algemeen!$BI$16:$BI$37
Name Gevolgkosten: Algemeen!$BI$16:$BI$37
Name ini_periode: Algemeen!$CV$16:$CV$37
Name interval_groot_onderhoud: Algemeen!$R$10
Name Invoerrij: Algemeen!$A$16
Name kol_delta_kosten: Algemeen!$EN$11
Name kol_delta_ONB_aanvang: Algemeen!$EP$11
Name kol_delta_ONB_missie: Algemeen!$EO$11
Name kol_delta_stfrf: Algemeen!$EM$11
Name kol_OH_kosten: Algemeen!$AY$11
Name kol_ONB_aanvang: Algemeen!$EG$11
Name kol_ONB_missie: Algemeen!$DX$11
Name kol_opmerkingen: Algemeen!$EI$11
Name Kosten_res_jaar: Algemeen!$BC$16:$BC$37
Name Kosten_res_pk: Algemeen!$BA$16:$BA$37

Sheet Managementrapportage
B2: =CONCATENATE("Instandhoudingskosten & prestaties | ",Algemeen!R4)
B3: =CONCATENATE("Beheerder: ",Algemeen!R3," | ",Algemeen!O3," object(en) · ",Algemeen!O5," tochten per jaar van ",Algemeen!O6," dagen · looptijd ",Looptijd," jaar"," | bron: IHCKWANT-model")
B4: Rapportagedatum: | Q4: =TODAY()
B5: Onderhoudskosten | E5: Kosten looptijd | H5: Aandeel correctief | K5: Storingen | N5: Storingsvrije tocht | Q5: Niet-beschikbaar
B6: =tot_OH | E6: =(tot_OH+tot_resdel_kosten+tot_OH_gevolg)*Looptijd | H6: =IF(tot_OH=0,0,SAO!AP21/tot_OH) | K6: =tot_storingsfreq*8760 | N6: =EXP(-tot_storingsfrequentie_missie*Missieduur) | Q6: =tot_ONB_missie
B7: per jaar · PO + TAO + correctief | E7: =CONCATENATE("totaal over ",Looptijd," jaar") | H7: van de onderhoudskosten | K7: per jaar · alle componenten | N7: kans op een tocht zonder storing | Q7: aandeel van de tochttijd
B9: Waar gaat het geld naartoe?
B10: Onderhoudskosten per jaar, verdeeld naar onderhoudssoort en naar component.
B27: Kosten over de looptijd en betrouwbaarheid
B28: Cumulatieve kosten over de gehele looptijd en de storingsfrequentie per functie.
B47: Uitgangspunten en herkomst
B48: Alle cijfers komen rechtstreeks uit het rekenmodel; op dit tabblad wordt niets ingevoerd.
B49: Aantal objecten | F49: =Algemeen!O3 | I49: Controle werklijsten vs. Algemeen | M49: =Rapportdata!C68
B50: Tochten per jaar | F50: =Algemeen!O5 | I50: Kosten reservedelen per jaar | M50: =tot_resdel_kosten
B51: Dagen per tocht | F51: =Algemeen!O6 | I51: Gevolgkosten per jaar | M51: =tot_OH_gevolg
B52: Looptijd (jaar) | F52: =Looptijd | I52: Kans niet beschikbaar bij start tocht | M52: =tot_ONB_aanvang
B53: Interval groot onderhoud (jaar) | F53: =Algemeen!O10 | I53: Aantal functies in het model | M53: =COUNTIF(Rapportdata!$B$98:$B$107,"?*")
B54: Uurtarief verhuurder / huurder / monteur | F54: =CONCATENATE("€ ",TEXT(Algemeen!AP14,"0")," / € ",TEXT(Algemeen!AQ14,"0")," / € ",TEXT(Algemeen!AR14,"0")) | I54: Controle componenten vs. totaal | M54: =Rapportdata!C66
B56: PO = periodiek onderhoud · TAO = toestandsafhankelijk onderhoud · SAO = correctief onderhoud. Storingsvrije tocht is de kans dat een tocht zonder storing wordt afgerond; niet-beschikbaar is het aandeel van de tochttijd dat het object niet inzetbaar is. Onderliggende berekeningen staan op het tabblad Algemeen, de rekenbladen van de grafieken op het tabblad Rapportdata.

Sheet Invoer
B2: Invoerblad
B3: Alles wat je invult staat op dit blad. De tabbladen Algemeen, PO, TAO en SAO vullen zichzelf, en de Managementrapportage rekent direct mee. Wit omrande cellen zijn invoervelden.
B5: 1. Object en gebruik
B6: Naam beheerder | L6: Fietsverhuurder
B7: Naam object | L7: Fiets
B8: Aantal objecten | L8: 1
B9: Aantal per inzet | L9: 1
B10: Aantal inzetten per jaar | L10: 30
B11: Dagen per inzet | L11: 5
B12: Looptijd (jaar) | L12: 10
B13: Interval groot onderhoud (jaar) | L13: 3
B15: 2. Uurtarieven | J15: (euro per uur, per uitvoerende partij)
B16: Verhuurder | L16: 20
B17: Huurder | L17: 100
B18: Monteur | L18: 50
B19: Partij 4 | L19: 100
B20: Partij 5 | L20: 100
B21: Partij 6 | L21: 100
B23: 3. Functies | J23: (prestaties waarop je rapporteert; niet gebruikte functies leeg laten)
B24: Functie 1 | L24: Fietsen
B25: Functie 2 | L25: Fietsen met verlichting
B26: Functie 3
B27: Functie 4
B28: Functie 5
B29: Functie 6
B30: Functie 7
B31: Functie 8
B32: Functie 9
B33: Functie 10
B35: 4. Onderhoudsregels | J35: (één regel per onderhoudsactie op één component)
B36: Structuur | L36: Component | O36: Onderhoudsactie | S36: Frequentie en uitvoering | X36: Uren per keer | AD36: Kosten per keer | AG36: Storingsgegevens | AJ36: Tijden (uur) | AQ36: Voorraad | AS36: Functies | BC36: Mensen per keer | BE36: Overig
A37: Nr | B37: N1 | C37: N2 | D37: N3 | E37: N4 | F37: N5 | G37: N6 | H37: N7 | I37: N8 | J37: N9 | K37: N10 | L37: Component | M37: Aantal | N37: Redun-dantie | O37: Soort onderhoud | P37: Uitbe-steden | Q37: Omschrijving | R37: Taak-ID | S37: Frequentie | T37: Een-heid | U37: Voor inzet | V37: Tijdens inzet | W37: Alleen GO | X37: Verhuur-der | Y37: Huurder | Z37: Monteur | AA37: Partij 4 | AB37: Partij 5 | AC37: Partij 6 | AD37: Vaste kosten | AE37: Reserve-delen | AF37: Gevolg-kosten | AG37: Storings-frequentie | AH37: % gebruik inzet | AI37: % gebruik overig | AJ37: Doorloop PO | AK37: Tijd TAO | AL37: Zoektijd | AM37: Reparatie-tijd | AN37: Wacht tijdens inzet | AO37: Bestel-tijd | AP37: Wacht locatie | AQ37: Delen mee | AR37: Voorraad start | AS37: F1 | AT37: F2 | AU37: F3 | AV37: F4 | AW37: F5 | AX37: F6 | AY37: F7 | AZ37: F8 | BA37: F9 | BB37: F10 | BC37: Mensen eigen | BD37: Mensen bedrijf | BE37: Opmerking | BG37: hulpkolommen (niet invullen)
A38: 1 | B38: 1 | L38: Fiets | M38: 1 | O38: PO - Inspectie (visueel) | Q38: Algehele controle van de toestand | S38: 1 | T38: w | U38: j | X38: 0.1 | AS38: x | BC38: 1 | BG38: =IF(LEFT($O38,3)="PO ",COUNTIF($O$38:$O38,"PO *"),"") | BH38: =IF(LEFT($O38,4)="TAO ",COUNTIF($O$38:$O38,"TAO *"),"") | BI38: =IF(LEFT($O38,3)="CO ",COUNTIF($O$38:$O38,"CO *"),"") | BK38: =IF($O38="PO - Inspectie (visueel)","x","") | BL38: =IF($O38="PO - Inspectie (meten)","x","") | BM38: =IF($O38="PO - Preservering","x","") | BN38: =IF($O38="PO - Revisie","x","") | BO38: =IF($O38="PO - Vervanging","x","") | BP38: =IF($O38="PO - Testen","x","") | BQ38: =IF($O38="TAO - Revisie","x","") | BR38: =IF($O38="TAO - Vervanging","x","") | BS38: =IF($O38="CO - Reparatie","x","") | BT38: =IF($O38="CO - Vervanging","x","") | BV38: =IF(N($S38)=0,"",1/$S38)
A39: 2 | B39: 1 | L39: Fiets | M39: 1 | O39: TAO - Vervanging | Q39: Afgeschreven | S39: 0.1 | T39: j | W39: j | X39: 4 | AD39: 2000 | AS39: x | BG39: =IF(LEFT($O39,3)="PO ",COUNTIF($O$38:$O39,"PO *"),"") | BH39: =IF(LEFT($O39,4)="TAO ",COUNTIF($O$38:$O39,"TAO *"),"") | BI39: =IF(LEFT($O39,3)="CO ",COUNTIF($O$38:$O39,"CO *"),"") | BK39: =IF($O39="PO - Inspectie (visueel)","x","") | BL39: =IF($O39="PO - Inspectie (meten)","x","") | BM39: =IF($O39="PO - Preservering","x","") | BN39: =IF($O39="PO - Revisie","x","") | BO39: =IF($O39="PO - Vervanging","x","") | BP39: =IF($O39="PO - Testen","x","") | BQ39: =IF($O39="TAO - Revisie","x","") | BR39: =IF($O39="TAO - Vervanging","x","") | BS39: =IF($O39="CO - Reparatie","x","") | BT39: =IF($O39="CO - Vervanging","x","") | BV39: =IF(N($S39)=0,"",1/$S39)
A40: 3 | B40: 1 | L40: Fiets | M40: 1 | AS40: x | BG40: =IF(LEFT($O40,3)="PO ",COUNTIF($O$38:$O40,"PO *"),"") | BH40: =IF(LEFT($O40,4)="TAO ",COUNTIF($O$38:$O40,"TAO *"),"") | BI40: =IF(LEFT($O40,3)="CO ",COUNTIF($O$38:$O40,"CO *"),"") | BK40: =IF($O40="PO - Inspectie (visueel)","x","") | BL40: =IF($O40="PO - Inspectie (meten)","x","") | BM40: =IF($O40="PO - Preservering","x","") | BN40: =IF($O40="PO - Revisie","x","") | BO40: =IF($O40="PO - Vervanging","x","") | BP40: =IF($O40="PO - Testen","x","") | BQ40: =IF($O40="TAO - Revisie","x","") | BR40: =IF($O40="TAO - Vervanging","x","") | BS40: =IF($O40="CO - Reparatie","x","") | BT40: =IF($O40="CO - Vervanging","x","") | BV40: =IF(N($S40)=0,"",1/$S40)
A41: 4 | B41: 1 | C41: 1 | L41: Aandrijving | M41: 1 | AS41: x | BG41: =IF(LEFT($O41,3)="PO ",COUNTIF($O$38:$O41,"PO *"),"") | BH41: =IF(LEFT($O41,4)="TAO ",COUNTIF($O$38:$O41,"TAO *"),"") | BI41: =IF(LEFT($O41,3)="CO ",COUNTIF($O$38:$O41,"CO *"),"") | BK41: =IF($O41="PO - Inspectie (visueel)","x","") | BL41: =IF($O41="PO - Inspectie (meten)","x","") | BM41: =IF($O41="PO - Preservering","x","") | BN41: =IF($O41="PO - Revisie","x","") | BO41: =IF($O41="PO - Vervanging","x","") | BP41: =IF($O41="PO - Testen","x","") | BQ41: =IF($O41="TAO - Revisie","x","") | BR41: =IF($O41="TAO - Vervanging","x","") | BS41: =IF($O41="CO - Reparatie","x","") | BT41: =IF($O41="CO - Vervanging","x","") | BV41: =IF(N($S41)=0,"",1/$S41)
A42: 5 | B42: 1 | C42: 1 | L42: Aandrijving | M42: 1 | AS42: x | BG42: =IF(LEFT($O42,3)="PO ",COUNTIF($O$38:$O42,"PO *"),"") | BH42: =IF(LEFT($O42,4)="TAO ",COUNTIF($O$38:$O42,"TAO *"),"") | BI42: =IF(LEFT($O42,3)="CO ",COUNTIF($O$38:$O42,"CO *"),"") | BK42: =IF($O42="PO - Inspectie (visueel)","x","") | BL42: =IF($O42="PO - Inspectie (meten)","x","") | BM42: =IF($O42="PO - Preservering","x","") | BN42: =IF($O42="PO - Revisie","x","") | BO42: =IF($O42="PO - Vervanging","x","") | BP42: =IF($O42="PO - Testen","x","") | BQ42: =IF($O42="TAO - Revisie","x","") | BR42: =IF($O42="TAO - Vervanging","x","") | BS42: =IF($O42="CO - Reparatie","x","") | BT42: =IF($O42="CO - Vervanging","x","") | BV42: =IF(N($S42)=0,"",1/$S42)
A43: 6 | B43: 1 | C43: 1 | L43: Aandrijving | M43: 1 | AS43: x | BG43: =IF(LEFT($O43,3)="PO ",COUNTIF($O$38:$O43,"PO *"),"") | BH43: =IF(LEFT($O43,4)="TAO ",COUNTIF($O$38:$O43,"TAO *"),"") | BI43: =IF(LEFT($O43,3)="CO ",COUNTIF($O$38:$O43,"CO *"),"") | BK43: =IF($O43="PO - Inspectie (visueel)","x","") | BL43: =IF($O43="PO - Inspectie (meten)","x","") | BM43: =IF($O43="PO - Preservering","x","") | BN43: =IF($O43="PO - Revisie","x","") | BO43: =IF($O43="PO - Vervanging","x","") | BP43: =IF($O43="PO - Testen","x","") | BQ43: =IF($O43="TAO - Revisie","x","") | BR43: =IF($O43="TAO - Vervanging","x","") | BS43: =IF($O43="CO - Reparatie","x","") | BT43: =IF($O43="CO - Vervanging","x","") | BV43: =IF(N($S43)=0,"",1/$S43)
A44: 7 | B44: 1 | C44: 1 | D44: 1 | L44: Ketting | M44: 1 | O44: PO - Preservering | Q44: Smeren | S44: 0.16666667 | T44: m | W44: j | Z44: 1 | AD44: 10 | AS44: x | BC44: 1 | BG44: =IF(LEFT($O44,3)="PO ",COUNTIF($O$38:$O44,"PO *"),"") | BH44: =IF(LEFT($O44,4)="TAO ",COUNTIF($O$38:$O44,"TAO *"),"") | BI44: =IF(LEFT($O44,3)="CO ",COUNTIF($O$38:$O44,"CO *"),"") | BK44: =IF($O44="PO - Inspectie (visueel)","x","") | BL44: =IF($O44="PO - Inspectie (meten)","x","") | BM44: =IF($O44="PO - Preservering","x","") | BN44: =IF($O44="PO - Revisie","x","") | BO44: =IF($O44="PO - Vervanging","x","") | BP44: =IF($O44="PO - Testen","x","") | BQ44: =IF($O44="TAO - Revisie","x","") | BR44: =IF($O44="TAO - Vervanging","x","") | BS44: =IF($O44="CO - Reparatie","x","") | BT44: =IF($O44="CO - Vervanging","x","") | BV44: =IF(N($S44)=0,"",1/$S44)
A45: 8 | B45: 1 | C45: 1 | D45: 1 | L45: Ketting | M45: 1 | AS45: x | BG45: =IF(LEFT($O45,3)="PO ",COUNTIF($O$38:$O45,"PO *"),"") | BH45: =IF(LEFT($O45,4)="TAO ",COUNTIF($O$38:$O45,"TAO *"),"") | BI45: =IF(LEFT($O45,3)="CO ",COUNTIF($O$38:$O45,"CO *"),"") | BK45: =IF($O45="PO - Inspectie (visueel)","x","") | BL45: =IF($O45="PO - Inspectie (meten)","x","") | BM45: =IF($O45="PO - Preservering","x","") | BN45: =IF($O45="PO - Revisie","x","") | BO45: =IF($O45="PO - Vervanging","x","") | BP45: =IF($O45="PO - Testen","x","") | BQ45: =IF($O45="TAO - Revisie","x","") | BR45: =IF($O45="TAO - Vervanging","x","") | BS45: =IF($O45="CO - Reparatie","x","") | BT45: =IF($O45="CO - Vervanging","x","") | BV45: =IF(N($S45)=0,"",1/$S45)
...

Sheet Handleiding
B2: IHCKWANT Fiets — één invoerblad
B3: Alle invoer staat op het tabblad Invoer. De rekenmodellen en formules van het model zijn niet gewijzigd.
B5: Zo is het bestand opgebouwd
B6: Invoer | C6: Het enige tabblad waarop je typt. Vijf blokken: 1 object en gebruik, 2 uurtarieven, 3 functies, 4 onderhoudsregels (20 regels), 5 controle.
B7: Managementrapportage | C7: Voorblad voor het management: zes kerncijfers en vier grafieken. Rekent direct mee met wat je op Invoer zet.
B8: PO / TAO / SAO | C8: De werklijsten. Ze vullen zichzelf: elke regel met "PO -", "TAO -" of "CO -" bij Soort onderhoud komt automatisch op het bijbehorende blad, in de volgorde van Invoer.
B9: Algemeen | C9: Het rekenblad van het model. De kopgegevens en de regels 18 t/m 37 worden gevuld vanuit Invoer; die cellen zijn beveiligd, zodat de koppeling niet per ongeluk wordt overschreven. De rekenkolommen erachter zijn onveranderd.
B10: Overzicht en Rapportdata | C10: Resultaten van het model en de rekenbladen achter de grafieken. Hier voer je niets in.
B11: Invullen in vijf stappen
B12: 1. Object en gebruik | C12: Naam van de beheerder en het object, aantal objecten, aantal per inzet, inzetten per jaar, dagen per inzet, looptijd in jaren en het interval voor groot onderhoud.
B13: 2. Uurtarieven | C13: De zes uurtarieven, in euro per uur. Ze gelden voor alle regels.
B14: 3. Functies | C14: De prestaties waarop je wilt rapporteren, bijvoorbeeld "Fietsen met verlichting". Functies die je niet gebruikt laat je leeg.
B15: 4. Onderhoudsregels | C15: Eén regel per onderhoudsactie op één component. Vul de decompositie (N1 t/m N10), de componentnaam, het aantal en de soort onderhoud uit de keuzelijst. Daarna frequentie en eenheid, uren per partij, kosten per keer, storingsgegevens, tijden, voorraad, het aantal mensen en de functies waaraan de regel bijdraagt (x).
B16: 5. Controle | C16: Hier zie je hoeveel regels je gebruikt en hoeveel er per werkblad beschikbaar zijn. Een rood getal betekent dat niet alle regels op dat werkblad passen.
B17: Goed om te weten
B18: Ruimte in het bestand | C18: 20 onderhoudsregels, waarvan maximaal 11 periodiek (PO), 9 toestandsafhankelijk (TAO) en 13 correctief (CO). Heb je meer regels nodig, dan breid ik het bestand uit; dat gaat niet met invoegen van rijen.
B19: Regel zonder onderhoudsactie | C19: Een regel met alleen een component telt mee in de decompositie en in de storingsberekening, maar komt niet op PO, TAO of SAO.
B20: Componentnaam | C20: Gebruik voor dezelfde component steeds dezelfde naam: de rapportage telt de kosten per naam bij elkaar op.
B21: Herberekenen | C21: Het bestand rekent automatisch door. Met F9 forceer je een herberekening.
B22: TTO en MJO op het blad PO | C22: De kolommen "In TTO1?", "In TTO2?" en "In MJO?" blijf je op het tabblad PO zelf zetten. Die formules kijken of de cel echt leeg is en werken daarom niet met een verwijzing naar Invoer.
B23: Bladbeveiliging | C23: De tabbladen zijn beveiligd zonder wachtwoord: formulecellen zijn beschermd, invoervelden niet. Via Controleren > Blad onbeveiligen haal je de beveiliging weg.
B24: Geen macro’s | C24: In dit bestand zit geen VBA. Alles werkt met formules, keuzelijsten en Excel zelf, dus het blijft werken als .xlsx.

Sheet PO
A1: 1 | C1: =Algemeen!R4 | T1: Periodieke onderhoudstaken | AV1: Periodieke onderhoudstaken
M3: Onderhoudsaktie | X3: Interv. | AA3: Uitvoering | AE3: tijd (uur)
A4: Deze lijst vult zichzelf vanuit het tabblad Invoer | K4: Fysieke decompositie | L4: Vermenigvuldigingsfactor onderhoudsactie | M4: Inspectie (visueel) | N4: Inspectie (Meten) | O4: Preservering | P4: Revisie | Q4: Vervanging | R4: Testen | T4: Omschrijving | V4: Taak-ID | X4: periodiciteit taak | Y4: d / w / m / j | AA4: Voor verhuur | AB4: Tijdens fietstocht | AC4: Alleen in groot onderhoud | AE4: Verhuurder | AF4: Huurder | AG4: Monteur | AH4: =Algemeen!AS13 | AI4: =Algemeen!AT13 | AJ4: =Algemeen!AU13 | AL4: # man | AN4: # man | AP4: Vaste kosten | AR4: OH-kosten per jaar | AT4: Doorlooptijd (uur) | AV4: Opmerkingen | AX4: In TTO1? (x) | AY4: OH-kosten TTO1 | AZ4: In TTO2? | BA4: OH-kosten TTO2 | BB4: In MJO? | BC4: OH-kosten MJO
AE5: =uurtarief_wd | AF5: 100 | AG5: 50 | AH5: 100 | AI5: 100 | AJ5: 100
A7: =IFERROR(N(INDEX(Invoer!$B$38:$B$57,MATCH(1,Invoer!$BG$38:$BG$57,0))),0) | B7: =IFERROR(N(INDEX(Invoer!$C$38:$C$57,MATCH(1,Invoer!$BG$38:$BG$57,0))),0) | C7: =IFERROR(N(INDEX(Invoer!$D$38:$D$57,MATCH(1,Invoer!$BG$38:$BG$57,0))),0) | D7: =IFERROR(N(INDEX(Invoer!$E$38:$E$57,MATCH(1,Invoer!$BG$38:$BG$57,0))),0) | E7: =IFERROR(N(INDEX(Invoer!$F$38:$F$57,MATCH(1,Invoer!$BG$38:$BG$57,0))),0) | F7: =IFERROR(N(INDEX(Invoer!$G$38:$G$57,MATCH(1,Invoer!$BG$38:$BG$57,0))),0) | G7: =IFERROR(N(INDEX(Invoer!$H$38:$H$57,MATCH(1,Invoer!$BG$38:$BG$57,0))),0) | H7: =IFERROR(N(INDEX(Invoer!$I$38:$I$57,MATCH(1,Invoer!$BG$38:$BG$57,0))),0) | I7: =IFERROR(N(INDEX(Invoer!$J$38:$J$57,MATCH(1,Invoer!$BG$38:$BG$57,0))),0) | J7: =IFERROR(N(INDEX(Invoer!$K$38:$K$57,MATCH(1,Invoer!$BG$38:$BG$57,0))),0) | K7: =IFERROR(IF(INDEX(Invoer!$L$38:$L$57,MATCH(1,Invoer!$BG$38:$BG$57,0))="","",INDEX(Invoer!$L$38:$L$57,MATCH(1,Invoer!$BG$38:$BG$57,0))),"") | L7: =IFERROR(N(INDEX(Invoer!$M$38:$M$57,MATCH(1,Invoer!$BG$38:$BG$57,0))),0) | M7: =IFERROR(IF(INDEX(Invoer!$BK$38:$BK$57,MATCH(1,Invoer!$BG$38:$BG$57,0))="","",INDEX(Invoer!$BK$38:$BK$57,MATCH(1,Invoer!$BG$38:$BG$57,0))),"") | N7: =IFERROR(IF(INDEX(Invoer!$BL$38:$BL$57,MATCH(1,Invoer!$BG$38:$BG$57,0))="","",INDEX(Invoer!$BL$38:$BL$57,MATCH(1,Invoer!$BG$38:$BG$57,0))),"") | O7: =IFERROR(IF(INDEX(Invoer!$BM$38:$BM$57,MATCH(1,Invoer!$BG$38:$BG$57,0))="","",INDEX(Invoer!$BM$38:$BM$57,MATCH(1,Invoer!$BG$38:$BG$57,0))),"") | P7: =IFERROR(IF(INDEX(Invoer!$BN$38:$BN$57,MATCH(1,Invoer!$BG$38:$BG$57,0))="","",INDEX(Invoer!$BN$38:$BN$57,MATCH(1,Invoer!$BG$38:$BG$57,0))),"") | Q7: =IFERROR(IF(INDEX(Invoer!$BO$38:$BO$57,MATCH(1,Invoer!$BG$38:$BG$57,0))="","",INDEX(Invoer!$BO$38:$BO$57,MATCH(1,Invoer!$BG$38:$BG$57,0))),"") | R7: =IFERROR(IF(INDEX(Invoer!$BP$38:$BP$57,MATCH(1,Invoer!$BG$38:$BG$57,0))="","",INDEX(Invoer!$BP$38:$BP$57,MATCH(1,Invoer!$BG$38:$BG$57,0))),"") | T7: =IFERROR(IF(INDEX(Invoer!$Q$38:$Q$57,MATCH(1,Invoer!$BG$38:$BG$57,0))="","",INDEX(Invoer!$Q$38:$Q$57,MATCH(1,Invoer!$BG$38:$BG$57,0))),"") | V7: =IFERROR(IF(INDEX(Invoer!$R$38:$R$57,MATCH(1,Invoer!$BG$38:$BG$57,0))="","",INDEX(Invoer!$R$38:$R$57,MATCH(1,Invoer!$BG$38:$BG$57,0))),"") | X7: =IFERROR(IF(N(INDEX(Invoer!$BV$38:$BV$57,MATCH(1,Invoer!$BG$38:$BG$57,0)))=0,"",INDEX(Invoer!$BV$38:$BV$57,MATCH(1,Invoer!$BG$38:$BG$57,0))),"") | Y7: =IFERROR(IF(INDEX(Invoer!$T$38:$T$57,MATCH(1,Invoer!$BG$38:$BG$57,0))="","",INDEX(Invoer!$T$38:$T$57,MATCH(1,Invoer!$BG$38:$BG$57,0))),"") | AA7: =IFERROR(IF(INDEX(Invoer!$U$38:$U$57,MATCH(1,Invoer!$BG$38:$BG$57,0))="","",INDEX(Invoer!$U$38:$U$57,MATCH(1,Invoer!$BG$38:$BG$57,0))),"") | AB7: =IFERROR(IF(INDEX(Invoer!$V$38:$V$57,MATCH(1,Invoer!$BG$38:$BG$57,0))="","",INDEX(Invoer!$V$38:$V$57,MATCH(1,Invoer!$BG$38:$BG$57,0))),"") | AC7: =IFERROR(IF(INDEX(Invoer!$W$38:$W$57,MATCH(1,Invoer!$BG$38:$BG$57,0))="","",INDEX(Invoer!$W$38:$W$57,MATCH(1,Invoer!$BG$38:$BG$57,0))),"") | AE7: =IFERROR(N(INDEX(Invoer!$X$38:$X$57,MATCH(1,Invoer!$BG$38:$BG$57,0))),0) | AF7: =IFERROR(N(INDEX(Invoer!$Y$38:$Y$57,MATCH(1,Invoer!$BG$38:$BG$57,0))),0) | AG7: =IFERROR(N(INDEX(Invoer!$Z$38:$Z$57,MATCH(1,Invoer!$BG$38:$BG$57,0))),0) | AH7: =IFERROR(N(INDEX(Invoer!$AA$38:$AA$57,MATCH(1,Invoer!$BG$38:$BG$57,0))),0) | AI7: =IFERROR(N(INDEX(Invoer!$AB$38:$AB$57,MATCH(1,Invoer!$BG$38:$BG$57,0))),0) | AJ7: =IFERROR(N(INDEX(Invoer!$AC$38:$AC$57,MATCH(1,Invoer!$BG$38:$BG$57,0))),0) | AL7: =IFERROR(N(INDEX(Invoer!$BC$38:$BC$57,MATCH(1,Invoer!$BG$38:$BG$57,0))),0) | AN7: =IFERROR(N(INDEX(Invoer!$BD$38:$BD$57,MATCH(1,Invoer!$BG$38:$BG$57,0))),0) | AP7: =IFERROR(N(INDEX(Invoer!$AD$38:$AD$57,MATCH(1,Invoer!$BG$38:$BG$57,0))),0) | AR7: =(IF(X7<>"",(utwd*(IF(ISNUMBER(AE7),AE7,0))+uttd*(IF(ISNUMBER(AF7),AF7,0))+utsb*(IF(ISNUMBER(AG7),AG7,0))+utrw*(IF(ISNUMBER(AH7),AH7,0))+utd*(IF(ISNUMBER(AI7),AI7,0))+_ut3*(IF(ISNUMBER(AJ7),AJ7,0)) +(IF(ISNUMBER(AP7),AP7,0)))*(IF(Y7="j",1,IF(Y7="m",12,IF(Y7="w",52,IF(Y7="d",365,0)))))/X7,0))*L7 | AT7: =IFERROR(N(INDEX(Invoer!$AJ$38:$AJ$57,MATCH(1,Invoer!$BG$38:$BG$57,0))),0) | AV7: =IFERROR(IF(INDEX(Invoer!$BE$38:$BE$57,MATCH(1,Invoer!$BG$38:$BG$57,0))="","",INDEX(Invoer!$BE$38:$BE$57,MATCH(1,Invoer!$BG$38:$BG$57,0))),"") | AY7: =IF(ISBLANK(AX7),0,(IF(X7<>"",(utwd*(IF(ISNUMBER(AE7),AE7,0))+uttd*(IF(ISNUMBER(AF7),AF7,0))+utsb*(IF(ISNUMBER(AG7),AG7,0))+utrw*(IF(ISNUMBER(AH7),AH7,0))+utd*(IF(ISNUMBER(AI7),AI7,0))+_ut3*(IF(ISNUMBER(AJ7),AJ7,0)) +(IF(ISNUMBER(AP7),AP7,0))),0))*L7) | BA7: =IF(ISBLANK(AZ7),0,(IF(X7<>"",(utwd*(IF(ISNUMBER(AE7),AE7,0))+uttd*(IF(ISNUMBER(AF7),AF7,0))+utsb*(IF(ISNUMBER(AG7),AG7,0))+utrw*(IF(ISNUMBER(AH7),AH7,0))+utd*(IF(ISNUMBER(AI7),AI7,0))+_ut3*(IF(ISNUMBER(AJ7),AJ7,0)) +(IF(ISNUMBER(AP7),AP7,0))),0))*L7) | BC7: =IF(ISBLANK(BB7),0,(IF(X7<>"",(utwd*(IF(ISNUMBER(AE7),AE7,0))+uttd*(IF(ISNUMBER(AF7),AF7,0))+utsb*(IF(ISNUMBER(AG7),AG7,0))+utrw*(IF(ISNUMBER(AH7),AH7,0))+utd*(IF(ISNUMBER(AI7),AI7,0))+_ut3*(IF(ISNUMBER(AJ7),AJ7,0)) +(IF(ISNUMBER(AP7),AP7,0))),0))*L7)
A8: =IFERROR(N(INDEX(Invoer!$B$38:$B$57,MATCH(2,Invoer!$BG$38:$BG$57,0))),0) | B8: =IFERROR(N(INDEX(Invoer!$C$38:$C$57,MATCH(2,Invoer!$BG$38:$BG$57,0))),0) | C8: =IFERROR(N(INDEX(Invoer!$D$38:$D$57,MATCH(2,Invoer!$BG$38:$BG$57,0))),0) | D8: =IFERROR(N(INDEX(Invoer!$E$38:$E$57,MATCH(2,Invoer!$BG$38:$BG$57,0))),0) | E8: =IFERROR(N(INDEX(Invoer!$F$38:$F$57,MATCH(2,Invoer!$BG$38:$BG$57,0))),0) | F8: =IFERROR(N(INDEX(Invoer!$G$38:$G$57,MATCH(2,Invoer!$BG$38:$BG$57,0))),0) | G8: =IFERROR(N(INDEX(Invoer!$H$38:$H$57,MATCH(2,Invoer!$BG$38:$BG$57,0))),0) | H8: =IFERROR(N(INDEX(Invoer!$I$38:$I$57,MATCH(2,Invoer!$BG$38:$BG$57,0))),0) | I8: =IFERROR(N(INDEX(Invoer!$J$38:$J$57,MATCH(2,Invoer!$BG$38:$BG$57,0))),0) | J8: =IFERROR(N(INDEX(Invoer!$K$38:$K$57,MATCH(2,Invoer!$BG$38:$BG$57,0))),0) | K8: =IFERROR(IF(INDEX(Invoer!$L$38:$L$57,MATCH(2,Invoer!$BG$38:$BG$57,0))="","",INDEX(Invoer!$L$38:$L$57,MATCH(2,Invoer!$BG$38:$BG$57,0))),"") | L8: =IFERROR(N(INDEX(Invoer!$M$38:$M$57,MATCH(2,Invoer!$BG$38:$BG$57,0))),0) | M8: =IFERROR(IF(INDEX(Invoer!$BK$38:$BK$57,MATCH(2,Invoer!$BG$38:$BG$57,0))="","",INDEX(Invoer!$BK$38:$BK$57,MATCH(2,Invoer!$BG$38:$BG$57,0))),"") | N8: =IFERROR(IF(INDEX(Invoer!$BL$38:$BL$57,MATCH(2,Invoer!$BG$38:$BG$57,0))="","",INDEX(Invoer!$BL$38:$BL$57,MATCH(2,Invoer!$BG$38:$BG$57,0))),"") | O8: =IFERROR(IF(INDEX(Invoer!$BM$38:$BM$57,MATCH(2,Invoer!$BG$38:$BG$57,0))="","",INDEX(Invoer!$BM$38:$BM$57,MATCH(2,Invoer!$BG$38:$BG$57,0))),"") | P8: =IFERROR(IF(INDEX(Invoer!$BN$38:$BN$57,MATCH(2,Invoer!$BG$38:$BG$57,0))="","",INDEX(Invoer!$BN$38:$BN$57,MATCH(2,Invoer!$BG$38:$BG$57,0))),"") | Q8: =IFERROR(IF(INDEX(Invoer!$BO$38:$BO$57,MATCH(2,Invoer!$BG$38:$BG$57,0))="","",INDEX(Invoer!$BO$38:$BO$57,MATCH(2,Invoer!$BG$38:$BG$57,0))),"") | R8: =IFERROR(IF(INDEX(Invoer!$BP$38:$BP$57,MATCH(2,Invoer!$BG$38:$BG$57,0))="","",INDEX(Invoer!$BP$38:$BP$57,MATCH(2,Invoer!$BG$38:$BG$57,0))),"") | T8: =IFERROR(IF(INDEX(Invoer!$Q$38:$Q$57,MATCH(2,Invoer!$BG$38:$BG$57,0))="","",INDEX(Invoer!$Q$38:$Q$57,MATCH(2,Invoer!$BG$38:$BG$57,0))),"") | V8: =IFERROR(IF(INDEX(Invoer!$R$38:$R$57,MATCH(2,Invoer!$BG$38:$BG$57,0))="","",INDEX(Invoer!$R$38:$R$57,MATCH(2,Invoer!$BG$38:$BG$57,0))),"") | X8: =IFERROR(IF(N(INDEX(Invoer!$BV$38:$BV$57,MATCH(2,Invoer!$BG$38:$BG$57,0)))=0,"",INDEX(Invoer!$BV$38:$BV$57,MATCH(2,Invoer!$BG$38:$BG$57,0))),"") | Y8: =IFERROR(IF(INDEX(Invoer!$T$38:$T$57,MATCH(2,Invoer!$BG$38:$BG$57,0))="","",INDEX(Invoer!$T$38:$T$57,MATCH(2,Invoer!$BG$38:$BG$57,0))),"") | AA8: =IFERROR(IF(INDEX(Invoer!$U$38:$U$57,MATCH(2,Invoer!$BG$38:$BG$57,0))="","",INDEX(Invoer!$U$38:$U$57,MATCH(2,Invoer!$BG$38:$BG$57,0))),"") | AB8: =IFERROR(IF(INDEX(Invoer!$V$38:$V$57,MATCH(2,Invoer!$BG$38:$BG$57,0))="","",INDEX(Invoer!$V$38:$V$57,MATCH(2,Invoer!$BG$38:$BG$57,0))),"") | AC8: =IFERROR(IF(INDEX(Invoer!$W$38:$W$57,MATCH(2,Invoer!$BG$38:$BG$57,0))="","",INDEX(Invoer!$W$38:$W$57,MATCH(2,Invoer!$BG$38:$BG$57,0))),"") | AE8: =IFERROR(N(INDEX(Invoer!$X$38:$X$57,MATCH(2,Invoer!$BG$38:$BG$57,0))),0) | AF8: =IFERROR(N(INDEX(Invoer!$Y$38:$Y$57,MATCH(2,Invoer!$BG$38:$BG$57,0))),0) | AG8: =IFERROR(N(INDEX(Invoer!$Z$38:$Z$57,MATCH(2,Invoer!$BG$38:$BG$57,0))),0) | AH8: =IFERROR(N(INDEX(Invoer!$AA$38:$AA$57,MATCH(2,Invoer!$BG$38:$BG$57,0))),0) | AI8: =IFERROR(N(INDEX(Invoer!$AB$38:$AB$57,MATCH(2,Invoer!$BG$38:$BG$57,0))),0) | AJ8: =IFERROR(N(INDEX(Invoer!$AC$38:$AC$57,MATCH(2,Invoer!$BG$38:$BG$57,0))),0) | AL8: =IFERROR(N(INDEX(Invoer!$BC$38:$BC$57,MATCH(2,Invoer!$BG$38:$BG$57,0))),0) | AN8: =IFERROR(N(INDEX(Invoer!$BD$38:$BD$57,MATCH(2,Invoer!$BG$38:$BG$57,0))),0) | AP8: =IFERROR(N(INDEX(Invoer!$AD$38:$AD$57,MATCH(2,Invoer!$BG$38:$BG$57,0))),0) | AR8: =(IF(X8<>"",(utwd*(IF(ISNUMBER(AE8),AE8,0))+uttd*(IF(ISNUMBER(AF8),AF8,0))+utsb*(IF(ISNUMBER(AG8),AG8,0))+utrw*(IF(ISNUMBER(AH8),AH8,0))+utd*(IF(ISNUMBER(AI8),AI8,0))+_ut3*(IF(ISNUMBER(AJ8),AJ8,0)) +(IF(ISNUMBER(AP8),AP8,0)))*(IF(Y8="j",1,IF(Y8="m",12,IF(Y8="w",52,IF(Y8="d",365,0)))))/X8,0))*L8 | AT8: =IFERROR(N(INDEX(Invoer!$AJ$38:$AJ$57,MATCH(2,Invoer!$BG$38:$BG$57,0))),0) | AV8: =IFERROR(IF(INDEX(Invoer!$BE$38:$BE$57,MATCH(2,Invoer!$BG$38:$BG$57,0))="","",INDEX(Invoer!$BE$38:$BE$57,MATCH(2,Invoer!$BG$38:$BG$57,0))),"") | AY8: =IF(ISBLANK(AX8),0,(IF(X8<>"",(utwd*(IF(ISNUMBER(AE8),AE8,0))+uttd*(IF(ISNUMBER(AF8),AF8,0))+utsb*(IF(ISNUMBER(AG8),AG8,0))+utrw*(IF(ISNUMBER(AH8),AH8,0))+utd*(IF(ISNUMBER(AI8),AI8,0))+_ut3*(IF(ISNUMBER(AJ8),AJ8,0)) +(IF(ISNUMBER(AP8),AP8,0))),0))*L8) | BA8: =IF(ISBLANK(AZ8),0,(IF(X8<>"",(utwd*(IF(ISNUMBER(AE8),AE8,0))+uttd*(IF(ISNUMBER(AF8),AF8,0))+utsb*(IF(ISNUMBER(AG8),AG8,0))+utrw*(IF(ISNUMBER(AH8),AH8,0))+utd*(IF(ISNUMBER(AI8),AI8,0))+_ut3*(IF(ISNUMBER(AJ8),AJ8,0)) +(IF(ISNUMBER(AP8),AP8,0))),0))*L8) | BC8: =IF(ISBLANK(BB8),0,(IF(X8<>"",(utwd*(IF(ISNUMBER(AE8),AE8,0))+uttd*(IF(ISNUMBER(AF8),AF8,0))+utsb*(IF(ISNUMBER(AG8),AG8,0))+utrw*(IF(ISNUMBER(AH8),AH8,0))+utd*(IF(ISNUMBER(AI8),AI8,0))+_ut3*(IF(ISNUMBER(AJ8),AJ8,0)) +(IF(ISNUMBER(AP8),AP8,0))),0))*L8)
A9: =IFERROR(N(INDEX(Invoer!$B$38:$B$57,MATCH(3,Invoer!$BG$38:$BG$57,0))),0) | B9: =IFERROR(N(INDEX(Invoer!$C$38:$C$57,MATCH(3,Invoer!$BG$38:$BG$57,0))),0) | C9: =IFERROR(N(INDEX(Invoer!$D$38:$D$57,MATCH(3,Invoer!$BG$38:$BG$57,0))),0) | D9: =IFERROR(N(INDEX(Invoer!$E$38:$E$57,MATCH(3,Invoer!$BG$38:$BG$57,0))),0) | E9: =IFERROR(N(INDEX(Invoer!$F$38:$F$57,MATCH(3,Invoer!$BG$38:$BG$57,0))),0) | F9: =IFERROR(N(INDEX(Invoer!$G$38:$G$57,MATCH(3,Invoer!$BG$38:$BG$57,0))),0) | G9: =IFERROR(N(INDEX(Invoer!$H$38:$H$57,MATCH(3,Invoer!$BG$38:$BG$57,0))),0) | H9: =IFERROR(N(INDEX(Invoer!$I$38:$I$57,MATCH(3,Invoer!$BG$38:$BG$57,0))),0) | I9: =IFERROR(N(INDEX(Invoer!$J$38:$J$57,MATCH(3,Invoer!$BG$38:$BG$57,0))),0) | J9: =IFERROR(N(INDEX(Invoer!$K$38:$K$57,MATCH(3,Invoer!$BG$38:$BG$57,0))),0) | K9: =IFERROR(IF(INDEX(Invoer!$L$38:$L$57,MATCH(3,Invoer!$BG$38:$BG$57,0))="","",INDEX(Invoer!$L$38:$L$57,MATCH(3,Invoer!$BG$38:$BG$57,0))),"") | L9: =IFERROR(N(INDEX(Invoer!$M$38:$M$57,MATCH(3,Invoer!$BG$38:$BG$57,0))),0) | M9: =IFERROR(IF(INDEX(Invoer!$BK$38:$BK$57,MATCH(3,Invoer!$BG$38:$BG$57,0))="","",INDEX(Invoer!$BK$38:$BK$57,MATCH(3,Invoer!$BG$38:$BG$57,0))),"") | N9: =IFERROR(IF(INDEX(Invoer!$BL$38:$BL$57,MATCH(3,Invoer!$BG$38:$BG$57,0))="","",INDEX(Invoer!$BL$38:$BL$57,MATCH(3,Invoer!$BG$38:$BG$57,0))),"") | O9: =IFERROR(IF(INDEX(Invoer!$BM$38:$BM$57,MATCH(3,Invoer!$BG$38:$BG$57,0))="","",INDEX(Invoer!$BM$38:$BM$57,MATCH(3,Invoer!$BG$38:$BG$57,0))),"") | P9: =IFERROR(IF(INDEX(Invoer!$BN$38:$BN$57,MATCH(3,Invoer!$BG$38:$BG$57,0))="","",INDEX(Invoer!$BN$38:$BN$57,MATCH(3,Invoer!$BG$38:$BG$57,0))),"") | Q9: =IFERROR(IF(INDEX(Invoer!$BO$38:$BO$57,MATCH(3,Invoer!$BG$38:$BG$57,0))="","",INDEX(Invoer!$BO$38:$BO$57,MATCH(3,Invoer!$BG$38:$BG$57,0))),"") | R9: =IFERROR(IF(INDEX(Invoer!$BP$38:$BP$57,MATCH(3,Invoer!$BG$38:$BG$57,0))="","",INDEX(Invoer!$BP$38:$BP$57,MATCH(3,Invoer!$BG$38:$BG$57,0))),"") | T9: =IFERROR(IF(INDEX(Invoer!$Q$38:$Q$57,MATCH(3,Invoer!$BG$38:$BG$57,0))="","",INDEX(Invoer!$Q$38:$Q$57,MATCH(3,Invoer!$BG$38:$BG$57,0))),"") | V9: =IFERROR(IF(INDEX(Invoer!$R$38:$R$57,MATCH(3,Invoer!$BG$38:$BG$57,0))="","",INDEX(Invoer!$R$38:$R$57,MATCH(3,Invoer!$BG$38:$BG$57,0))),"") | X9: =IFERROR(IF(N(INDEX(Invoer!$BV$38:$BV$57,MATCH(3,Invoer!$BG$38:$BG$57,0)))=0,"",INDEX(Invoer!$BV$38:$BV$57,MATCH(3,Invoer!$BG$38:$BG$57,0))),"") | Y9: =IFERROR(IF(INDEX(Invoer!$T$38:$T$57,MATCH(3,Invoer!$BG$38:$BG$57,0))="","",INDEX(Invoer!$T$38:$T$57,MATCH(3,Invoer!$BG$38:$BG$57,0))),"") | AA9: =IFERROR(IF(INDEX(Invoer!$U$38:$U$57,MATCH(3,Invoer!$BG$38:$BG$57,0))="","",INDEX(Invoer!$U$38:$U$57,MATCH(3,Invoer!$BG$38:$BG$57,0))),"") | AB9: =IFERROR(IF(INDEX(Invoer!$V$38:$V$57,MATCH(3,Invoer!$BG$38:$BG$57,0))="","",INDEX(Invoer!$V$38:$V$57,MATCH(3,Invoer!$BG$38:$BG$57,0))),"") | AC9: =IFERROR(IF(INDEX(Invoer!$W$38:$W$57,MATCH(3,Invoer!$BG$38:$BG$57,0))="","",INDEX(Invoer!$W$38:$W$57,MATCH(3,Invoer!$BG$38:$BG$57,0))),"") | AE9: =IFERROR(N(INDEX(Invoer!$X$38:$X$57,MATCH(3,Invoer!$BG$38:$BG$57,0))),0) | AF9: =IFERROR(N(INDEX(Invoer!$Y$38:$Y$57,MATCH(3,Invoer!$BG$38:$BG$57,0))),0) | AG9: =IFERROR(N(INDEX(Invoer!$Z$38:$Z$57,MATCH(3,Invoer!$BG$38:$BG$57,0))),0) | AH9: =IFERROR(N(INDEX(Invoer!$AA$38:$AA$57,MATCH(3,Invoer!$BG$38:$BG$57,0))),0) | AI9: =IFERROR(N(INDEX(Invoer!$AB$38:$AB$57,MATCH(3,Invoer!$BG$38:$BG$57,0))),0) | AJ9: =IFERROR(N(INDEX(Invoer!$AC$38:$AC$57,MATCH(3,Invoer!$BG$38:$BG$57,0))),0) | AL9: =IFERROR(N(INDEX(Invoer!$BC$38:$BC$57,MATCH(3,Invoer!$BG$38:$BG$57,0))),0) | AN9: =IFERROR(N(INDEX(Invoer!$BD$38:$BD$57,MATCH(3,Invoer!$BG$38:$BG$57,0))),0) | AP9: =IFERROR(N(INDEX(Invoer!$AD$38:$AD$57,MATCH(3,Invoer!$BG$38:$BG$57,0))),0) | AR9: =(IF(X9<>"",(utwd*(IF(ISNUMBER(AE9),AE9,0))+uttd*(IF(ISNUMBER(AF9),AF9,0))+utsb*(IF(ISNUMBER(AG9),AG9,0))+utrw*(IF(ISNUMBER(AH9),AH9,0))+utd*(IF(ISNUMBER(AI9),AI9,0))+_ut3*(IF(ISNUMBER(AJ9),AJ9,0)) +(IF(ISNUMBER(AP9),AP9,0)))*(IF(Y9="j",1,IF(Y9="m",12,IF(Y9="w",52,IF(Y9="d",365,0)))))/X9,0))*L9 | AT9: =IFERROR(N(INDEX(Invoer!$AJ$38:$AJ$57,MATCH(3,Invoer!$BG$38:$BG$57,0))),0) | AV9: =IFERROR(IF(INDEX(Invoer!$BE$38:$BE$57,MATCH(3,Invoer!$BG$38:$BG$57,0))="","",INDEX(Invoer!$BE$38:$BE$57,MATCH(3,Invoer!$BG$38:$BG$57,0))),"") | AY9: =IF(ISBLANK(AX9),0,(IF(X9<>"",(utwd*(IF(ISNUMBER(AE9),AE9,0))+uttd*(IF(ISNUMBER(AF9),AF9,0))+utsb*(IF(ISNUMBER(AG9),AG9,0))+utrw*(IF(ISNUMBER(AH9),AH9,0))+utd*(IF(ISNUMBER(AI9),AI9,0))+_ut3*(IF(ISNUMBER(AJ9),AJ9,0)) +(IF(ISNUMBER(AP9),AP9,0))),0))*L9) | BA9: =IF(ISBLANK(AZ9),0,(IF(X9<>"",(utwd*(IF(ISNUMBER(AE9),AE9,0))+uttd*(IF(ISNUMBER(AF9),AF9,0))+utsb*(IF(ISNUMBER(AG9),AG9,0))+utrw*(IF(ISNUMBER(AH9),AH9,0))+utd*(IF(ISNUMBER(AI9),AI9,0))+_ut3*(IF(ISNUMBER(AJ9),AJ9,0)) +(IF(ISNUMBER(AP9),AP9,0))),0))*L9) | BC9: =IF(ISBLANK(BB9),0,(IF(X9<>"",(utwd*(IF(ISNUMBER(AE9),AE9,0))+uttd*(IF(ISNUMBER(AF9),AF9,0))+utsb*(IF(ISNUMBER(AG9),AG9,0))+utrw*(IF(ISNUMBER(AH9),AH9,0))+utd*(IF(ISNUMBER(AI9),AI9,0))+_ut3*(IF(ISNUMBER(AJ9),AJ9,0)) +(IF(ISNUMBER(AP9),AP9,0))),0))*L9)
A10: =IFERROR(N(INDEX(Invoer!$B$38:$B$57,MATCH(4,Invoer!$BG$38:$BG$57,0))),0) | B10: =IFERROR(N(INDEX(Invoer!$C$38:$C$57,MATCH(4,Invoer!$BG$38:$BG$57,0))),0) | C10: =IFERROR(N(INDEX(Invoer!$D$38:$D$57,MATCH(4,Invoer!$BG$38:$BG$57,0))),0) | D10: =IFERROR(N(INDEX(Invoer!$E$38:$E$57,MATCH(4,Invoer!$BG$38:$BG$57,0))),0) | E10: =IFERROR(N(INDEX(Invoer!$F$38:$F$57,MATCH(4,Invoer!$BG$38:$BG$57,0))),0) | F10: =IFERROR(N(INDEX(Invoer!$G$38:$G$57,MATCH(4,Invoer!$BG$38:$BG$57,0))),0) | G10: =IFERROR(N(INDEX(Invoer!$H$38:$H$57,MATCH(4,Invoer!$BG$38:$BG$57,0))),0) | H10: =IFERROR(N(INDEX(Invoer!$I$38:$I$57,MATCH(4,Invoer!$BG$38:$BG$57,0))),0) | I10: =IFERROR(N(INDEX(Invoer!$J$38:$J$57,MATCH(4,Invoer!$BG$38:$BG$57,0))),0) | J10: =IFERROR(N(INDEX(Invoer!$K$38:$K$57,MATCH(4,Invoer!$BG$38:$BG$57,0))),0) | K10: =IFERROR(IF(INDEX(Invoer!$L$38:$L$57,MATCH(4,Invoer!$BG$38:$BG$57,0))="","",INDEX(Invoer!$L$38:$L$57,MATCH(4,Invoer!$BG$38:$BG$57,0))),"") | L10: =IFERROR(N(INDEX(Invoer!$M$38:$M$57,MATCH(4,Invoer!$BG$38:$BG$57,0))),0) | M10: =IFERROR(IF(INDEX(Invoer!$BK$38:$BK$57,MATCH(4,Invoer!$BG$38:$BG$57,0))="","",INDEX(Invoer!$BK$38:$BK$57,MATCH(4,Invoer!$BG$38:$BG$57,0))),"") | N10: =IFERROR(IF(INDEX(Invoer!$BL$38:$BL$57,MATCH(4,Invoer!$BG$38:$BG$57,0))="","",INDEX(Invoer!$BL$38:$BL$57,MATCH(4,Invoer!$BG$38:$BG$57,0))),"") | O10: =IFERROR(IF(INDEX(Invoer!$BM$38:$BM$57,MATCH(4,Invoer!$BG$38:$BG$57,0))="","",INDEX(Invoer!$BM$38:$BM$57,MATCH(4,Invoer!$BG$38:$BG$57,0))),"") | P10: =IFERROR(IF(INDEX(Invoer!$BN$38:$BN$57,MATCH(4,Invoer!$BG$38:$BG$57,0))="","",INDEX(Invoer!$BN$38:$BN$57,MATCH(4,Invoer!$BG$38:$BG$57,0))),"") | Q10: =IFERROR(IF(INDEX(Invoer!$BO$38:$BO$57,MATCH(4,Invoer!$BG$38:$BG$57,0))="","",INDEX(Invoer!$BO$38:$BO$57,MATCH(4,Invoer!$BG$38:$BG$57,0))),"") | R10: =IFERROR(IF(INDEX(Invoer!$BP$38:$BP$57,MATCH(4,Invoer!$BG$38:$BG$57,0))="","",INDEX(Invoer!$BP$38:$BP$57,MATCH(4,Invoer!$BG$38:$BG$57,0))),"") | T10: =IFERROR(IF(INDEX(Invoer!$Q$38:$Q$57,MATCH(4,Invoer!$BG$38:$BG$57,0))="","",INDEX(Invoer!$Q$38:$Q$57,MATCH(4,Invoer!$BG$38:$BG$57,0))),"") | V10: =IFERROR(IF(INDEX(Invoer!$R$38:$R$57,MATCH(4,Invoer!$BG$38:$BG$57,0))="","",INDEX(Invoer!$R$38:$R$57,MATCH(4,Invoer!$BG$38:$BG$57,0))),"") | X10: =IFERROR(IF(N(INDEX(Invoer!$BV$38:$BV$57,MATCH(4,Invoer!$BG$38:$BG$57,0)))=0,"",INDEX(Invoer!$BV$38:$BV$57,MATCH(4,Invoer!$BG$38:$BG$57,0))),"") | Y10: =IFERROR(IF(INDEX(Invoer!$T$38:$T$57,MATCH(4,Invoer!$BG$38:$BG$57,0))="","",INDEX(Invoer!$T$38:$T$57,MATCH(4,Invoer!$BG$38:$BG$57,0))),"") | AA10: =IFERROR(IF(INDEX(Invoer!$U$38:$U$57,MATCH(4,Invoer!$BG$38:$BG$57,0))="","",INDEX(Invoer!$U$38:$U$57,MATCH(4,Invoer!$BG$38:$BG$57,0))),"") | AB10: =IFERROR(IF(INDEX(Invoer!$V$38:$V$57,MATCH(4,Invoer!$BG$38:$BG$57,0))="","",INDEX(Invoer!$V$38:$V$57,MATCH(4,Invoer!$BG$38:$BG$57,0))),"") | AC10: =IFERROR(IF(INDEX(Invoer!$W$38:$W$57,MATCH(4,Invoer!$BG$38:$BG$57,0))="","",INDEX(Invoer!$W$38:$W$57,MATCH(4,Invoer!$BG$38:$BG$57,0))),"") | AE10: =IFERROR(N(INDEX(Invoer!$X$38:$X$57,MATCH(4,Invoer!$BG$38:$BG$57,0))),0) | AF10: =IFERROR(N(INDEX(Invoer!$Y$38:$Y$57,MATCH(4,Invoer!$BG$38:$BG$57,0))),0) | AG10: =IFERROR(N(INDEX(Invoer!$Z$38:$Z$57,MATCH(4,Invoer!$BG$38:$BG$57,0))),0) | AH10: =IFERROR(N(INDEX(Invoer!$AA$38:$AA$57,MATCH(4,Invoer!$BG$38:$BG$57,0))),0) | AI10: =IFERROR(N(INDEX(Invoer!$AB$38:$AB$57,MATCH(4,Invoer!$BG$38:$BG$57,0))),0) | AJ10: =IFERROR(N(INDEX(Invoer!$AC$38:$AC$57,MATCH(4,Invoer!$BG$38:$BG$57,0))),0) | AL10: =IFERROR(N(INDEX(Invoer!$BC$38:$BC$57,MATCH(4,Invoer!$BG$38:$BG$57,0))),0) | AN10: =IFERROR(N(INDEX(Invoer!$BD$38:$BD$57,MATCH(4,Invoer!$BG$38:$BG$57,0))),0) | AP10: =IFERROR(N(INDEX(Invoer!$AD$38:$AD$57,MATCH(4,Invoer!$BG$38:$BG$57,0))),0) | AR10: =(IF(X10<>"",(utwd*(IF(ISNUMBER(AE10),AE10,0))+uttd*(IF(ISNUMBER(AF10),AF10,0))+utsb*(IF(ISNUMBER(AG10),AG10,0))+utrw*(IF(ISNUMBER(AH10),AH10,0))+utd*(IF(ISNUMBER(AI10),AI10,0))+_ut3*(IF(ISNUMBER(AJ10),AJ10,0)) +(IF(ISNUMBER(AP10),AP10,0)))*(IF(Y10="j",1,IF(Y10="m",12,IF(Y10="w",52,IF(Y10="d",365,0)))))/X10,0))*L10 | AT10: =IFERROR(N(INDEX(Invoer!$AJ$38:$AJ$57,MATCH(4,Invoer!$BG$38:$BG$57,0))),0) | AV10: =IFERROR(IF(INDEX(Invoer!$BE$38:$BE$57,MATCH(4,Invoer!$BG$38:$BG$57,0))="","",INDEX(Invoer!$BE$38:$BE$57,MATCH(4,Invoer!$BG$38:$BG$57,0))),"") | AY10: =IF(ISBLANK(AX10),0,(IF(X10<>"",(utwd*(IF(ISNUMBER(AE10),AE10,0))+uttd*(IF(ISNUMBER(AF10),AF10,0))+utsb*(IF(ISNUMBER(AG10),AG10,0))+utrw*(IF(ISNUMBER(AH10),AH10,0))+utd*(IF(ISNUMBER(AI10),AI10,0))+_ut3*(IF(ISNUMBER(AJ10),AJ10,0)) +(IF(ISNUMBER(AP10),AP10,0))),0))*L10) | BA10: =IF(ISBLANK(AZ10),0,(IF(X10<>"",(utwd*(IF(ISNUMBER(AE10),AE10,0))+uttd*(IF(ISNUMBER(AF10),AF10,0))+utsb*(IF(ISNUMBER(AG10),AG10,0))+utrw*(IF(ISNUMBER(AH10),AH10,0))+utd*(IF(ISNUMBER(AI10),AI10,0))+_ut3*(IF(ISNUMBER(AJ10),AJ10,0)) +(IF(ISNUMBER(AP10),AP10,0))),0))*L10) | BC10: =IF(ISBLANK(BB10),0,(IF(X10<>"",(utwd*(IF(ISNUMBER(AE10),AE10,0))+uttd*(IF(ISNUMBER(AF10),AF10,0))+utsb*(IF(ISNUMBER(AG10),AG10,0))+utrw*(IF(ISNUMBER(AH10),AH10,0))+utd*(IF(ISNUMBER(AI10),AI10,0))+_ut3*(IF(ISNUMBER(AJ10),AJ10,0)) +(IF(ISNUMBER(AP10),AP10,0))),0))*L10)
A11: =IFERROR(N(INDEX(Invoer!$B$38:$B$57,MATCH(5,Invoer!$BG$38:$BG$57,0))),0) | B11: =IFERROR(N(INDEX(Invoer!$C$38:$C$57,MATCH(5,Invoer!$BG$38:$BG$57,0))),0) | C11: =IFERROR(N(INDEX(Invoer!$D$38:$D$57,MATCH(5,Invoer!$BG$38:$BG$57,0))),0) | D11: =IFERROR(N(INDEX(Invoer!$E$38:$E$57,MATCH(5,Invoer!$BG$38:$BG$57,0))),0) | E11: =IFERROR(N(INDEX(Invoer!$F$38:$F$57,MATCH(5,Invoer!$BG$38:$BG$57,0))),0) | F11: =IFERROR(N(INDEX(Invoer!$G$38:$G$57,MATCH(5,Invoer!$BG$38:$BG$57,0))),0) | G11: =IFERROR(N(INDEX(Invoer!$H$38:$H$57,MATCH(5,Invoer!$BG$38:$BG$57,0))),0) | H11: =IFERROR(N(INDEX(Invoer!$I$38:$I$57,MATCH(5,Invoer!$BG$38:$BG$57,0))),0) | I11: =IFERROR(N(INDEX(Invoer!$J$38:$J$57,MATCH(5,Invoer!$BG$38:$BG$57,0))),0) | J11: =IFERROR(N(INDEX(Invoer!$K$38:$K$57,MATCH(5,Invoer!$BG$38:$BG$57,0))),0) | K11: =IFERROR(IF(INDEX(Invoer!$L$38:$L$57,MATCH(5,Invoer!$BG$38:$BG$57,0))="","",INDEX(Invoer!$L$38:$L$57,MATCH(5,Invoer!$BG$38:$BG$57,0))),"") | L11: =IFERROR(N(INDEX(Invoer!$M$38:$M$57,MATCH(5,Invoer!$BG$38:$BG$57,0))),0) | M11: =IFERROR(IF(INDEX(Invoer!$BK$38:$BK$57,MATCH(5,Invoer!$BG$38:$BG$57,0))="","",INDEX(Invoer!$BK$38:$BK$57,MATCH(5,Invoer!$BG$38:$BG$57,0))),"") | N11: =IFERROR(IF(INDEX(Invoer!$BL$38:$BL$57,MATCH(5,Invoer!$BG$38:$BG$57,0))="","",INDEX(Invoer!$BL$38:$BL$57,MATCH(5,Invoer!$BG$38:$BG$57,0))),"") | O11: =IFERROR(IF(INDEX(Invoer!$BM$38:$BM$57,MATCH(5,Invoer!$BG$38:$BG$57,0))="","",INDEX(Invoer!$BM$38:$BM$57,MATCH(5,Invoer!$BG$38:$BG$57,0))),"") | P11: =IFERROR(IF(INDEX(Invoer!$BN$38:$BN$57,MATCH(5,Invoer!$BG$38:$BG$57,0))="","",INDEX(Invoer!$BN$38:$BN$57,MATCH(5,Invoer!$BG$38:$BG$57,0))),"") | Q11: =IFERROR(IF(INDEX(Invoer!$BO$38:$BO$57,MATCH(5,Invoer!$BG$38:$BG$57,0))="","",INDEX(Invoer!$BO$38:$BO$57,MATCH(5,Invoer!$BG$38:$BG$57,0))),"") | R11: =IFERROR(IF(INDEX(Invoer!$BP$38:$BP$57,MATCH(5,Invoer!$BG$38:$BG$57,0))="","",INDEX(Invoer!$BP$38:$BP$57,MATCH(5,Invoer!$BG$38:$BG$57,0))),"") | T11: =IFERROR(IF(INDEX(Invoer!$Q$38:$Q$57,MATCH(5,Invoer!$BG$38:$BG$57,0))="","",INDEX(Invoer!$Q$38:$Q$57,MATCH(5,Invoer!$BG$38:$BG$57,0))),"") | V11: =IFERROR(IF(INDEX(Invoer!$R$38:$R$57,MATCH(5,Invoer!$BG$38:$BG$57,0))="","",INDEX(Invoer!$R$38:$R$57,MATCH(5,Invoer!$BG$38:$BG$57,0))),"") | X11: =IFERROR(IF(N(INDEX(Invoer!$BV$38:$BV$57,MATCH(5,Invoer!$BG$38:$BG$57,0)))=0,"",INDEX(Invoer!$BV$38:$BV$57,MATCH(5,Invoer!$BG$38:$BG$57,0))),"") | Y11: =IFERROR(IF(INDEX(Invoer!$T$38:$T$57,MATCH(5,Invoer!$BG$38:$BG$57,0))="","",INDEX(Invoer!$T$38:$T$57,MATCH(5,Invoer!$BG$38:$BG$57,0))),"") | AA11: =IFERROR(IF(INDEX(Invoer!$U$38:$U$57,MATCH(5,Invoer!$BG$38:$BG$57,0))="","",INDEX(Invoer!$U$38:$U$57,MATCH(5,Invoer!$BG$38:$BG$57,0))),"") | AB11: =IFERROR(IF(INDEX(Invoer!$V$38:$V$57,MATCH(5,Invoer!$BG$38:$BG$57,0))="","",INDEX(Invoer!$V$38:$V$57,MATCH(5,Invoer!$BG$38:$BG$57,0))),"") | AC11: =IFERROR(IF(INDEX(Invoer!$W$38:$W$57,MATCH(5,Invoer!$BG$38:$BG$57,0))="","",INDEX(Invoer!$W$38:$W$57,MATCH(5,Invoer!$BG$38:$BG$57,0))),"") | AE11: =IFERROR(N(INDEX(Invoer!$X$38:$X$57,MATCH(5,Invoer!$BG$38:$BG$57,0))),0) | AF11: =IFERROR(N(INDEX(Invoer!$Y$38:$Y$57,MATCH(5,Invoer!$BG$38:$BG$57,0))),0) | AG11: =IFERROR(N(INDEX(Invoer!$Z$38:$Z$57,MATCH(5,Invoer!$BG$38:$BG$57,0))),0) | AH11: =IFERROR(N(INDEX(Invoer!$AA$38:$AA$57,MATCH(5,Invoer!$BG$38:$BG$57,0))),0) | AI11: =IFERROR(N(INDEX(Invoer!$AB$38:$AB$57,MATCH(5,Invoer!$BG$38:$BG$57,0))),0) | AJ11: =IFERROR(N(INDEX(Invoer!$AC$38:$AC$57,MATCH(5,Invoer!$BG$38:$BG$57,0))),0) | AL11: =IFERROR(N(INDEX(Invoer!$BC$38:$BC$57,MATCH(5,Invoer!$BG$38:$BG$57,0))),0) | AN11: =IFERROR(N(INDEX(Invoer!$BD$38:$BD$57,MATCH(5,Invoer!$BG$38:$BG$57,0))),0) | AP11: =IFERROR(N(INDEX(Invoer!$AD$38:$AD$57,MATCH(5,Invoer!$BG$38:$BG$57,0))),0) | AR11: =(IF(X11<>"",(utwd*(IF(ISNUMBER(AE11),AE11,0))+uttd*(IF(ISNUMBER(AF11),AF11,0))+utsb*(IF(ISNUMBER(AG11),AG11,0))+utrw*(IF(ISNUMBER(AH11),AH11,0))+utd*(IF(ISNUMBER(AI11),AI11,0))+_ut3*(IF(ISNUMBER(AJ11),AJ11,0)) +(IF(ISNUMBER(AP11),AP11,0)))*(IF(Y11="j",1,IF(Y11="m",12,IF(Y11="w",52,IF(Y11="d",365,0)))))/X11,0))*L11 | AT11: =IFERROR(N(INDEX(Invoer!$AJ$38:$AJ$57,MATCH(5,Invoer!$BG$38:$BG$57,0))),0) | AV11: =IFERROR(IF(INDEX(Invoer!$BE$38:$BE$57,MATCH(5,Invoer!$BG$38:$BG$57,0))="","",INDEX(Invoer!$BE$38:$BE$57,MATCH(5,Invoer!$BG$38:$BG$57,0))),"") | AY11: =IF(ISBLANK(AX11),0,(IF(X11<>"",(utwd*(IF(ISNUMBER(AE11),AE11,0))+uttd*(IF(ISNUMBER(AF11),AF11,0))+utsb*(IF(ISNUMBER(AG11),AG11,0))+utrw*(IF(ISNUMBER(AH11),AH11,0))+utd*(IF(ISNUMBER(AI11),AI11,0))+_ut3*(IF(ISNUMBER(AJ11),AJ11,0)) +(IF(ISNUMBER(AP11),AP11,0))),0))*L11) | BA11: =IF(ISBLANK(AZ11),0,(IF(X11<>"",(utwd*(IF(ISNUMBER(AE11),AE11,0))+uttd*(IF(ISNUMBER(AF11),AF11,0))+utsb*(IF(ISNUMBER(AG11),AG11,0))+utrw*(IF(ISNUMBER(AH11),AH11,0))+utd*(IF(ISNUMBER(AI11),AI11,0))+_ut3*(IF(ISNUMBER(AJ11),AJ11,0)) +(IF(ISNUMBER(AP11),AP11,0))),0))*L11) | BC11: =IF(ISBLANK(BB11),0,(IF(X11<>"",(utwd*(IF(ISNUMBER(AE11),AE11,0))+uttd*(IF(ISNUMBER(AF11),AF11,0))+utsb*(IF(ISNUMBER(AG11),AG11,0))+utrw*(IF(ISNUMBER(AH11),AH11,0))+utd*(IF(ISNUMBER(AI11),AI11,0))+_ut3*(IF(ISNUMBER(AJ11),AJ11,0)) +(IF(ISNUMBER(AP11),AP11,0))),0))*L11)
A12: =IFERROR(N(INDEX(Invoer!$B$38:$B$57,MATCH(6,Invoer!$BG$38:$BG$57,0))),0) | B12: =IFERROR(N(INDEX(Invoer!$C$38:$C$57,MATCH(6,Invoer!$BG$38:$BG$57,0))),0) | C12: =IFERROR(N(INDEX(Invoer!$D$38:$D$57,MATCH(6,Invoer!$BG$38:$BG$57,0))),0) | D12: =IFERROR(N(INDEX(Invoer!$E$38:$E$57,MATCH(6,Invoer!$BG$38:$BG$57,0))),0) | E12: =IFERROR(N(INDEX(Invoer!$F$38:$F$57,MATCH(6,Invoer!$BG$38:$BG$57,0))),0) | F12: =IFERROR(N(INDEX(Invoer!$G$38:$G$57,MATCH(6,Invoer!$BG$38:$BG$57,0))),0) | G12: =IFERROR(N(INDEX(Invoer!$H$38:$H$57,MATCH(6,Invoer!$BG$38:$BG$57,0))),0) | H12: =IFERROR(N(INDEX(Invoer!$I$38:$I$57,MATCH(6,Invoer!$BG$38:$BG$57,0))),0) | I12: =IFERROR(N(INDEX(Invoer!$J$38:$J$57,MATCH(6,Invoer!$BG$38:$BG$57,0))),0) | J12: =IFERROR(N(INDEX(Invoer!$K$38:$K$57,MATCH(6,Invoer!$BG$38:$BG$57,0))),0) | K12: =IFERROR(IF(INDEX(Invoer!$L$38:$L$57,MATCH(6,Invoer!$BG$38:$BG$57,0))="","",INDEX(Invoer!$L$38:$L$57,MATCH(6,Invoer!$BG$38:$BG$57,0))),"") | L12: =IFERROR(N(INDEX(Invoer!$M$38:$M$57,MATCH(6,Invoer!$BG$38:$BG$57,0))),0) | M12: =IFERROR(IF(INDEX(Invoer!$BK$38:$BK$57,MATCH(6,Invoer!$BG$38:$BG$57,0))="","",INDEX(Invoer!$BK$38:$BK$57,MATCH(6,Invoer!$BG$38:$BG$57,0))),"") | N12: =IFERROR(IF(INDEX(Invoer!$BL$38:$BL$57,MATCH(6,Invoer!$BG$38:$BG$57,0))="","",INDEX(Invoer!$BL$38:$BL$57,MATCH(6,Invoer!$BG$38:$BG$57,0))),"") | O12: =IFERROR(IF(INDEX(Invoer!$BM$38:$BM$57,MATCH(6,Invoer!$BG$38:$BG$57,0))="","",INDEX(Invoer!$BM$38:$BM$57,MATCH(6,Invoer!$BG$38:$BG$57,0))),"") | P12: =IFERROR(IF(INDEX(Invoer!$BN$38:$BN$57,MATCH(6,Invoer!$BG$38:$BG$57,0))="","",INDEX(Invoer!$BN$38:$BN$57,MATCH(6,Invoer!$BG$38:$BG$57,0))),"") | Q12: =IFERROR(IF(INDEX(Invoer!$BO$38:$BO$57,MATCH(6,Invoer!$BG$38:$BG$57,0))="","",INDEX(Invoer!$BO$38:$BO$57,MATCH(6,Invoer!$BG$38:$BG$57,0))),"") | R12: =IFERROR(IF(INDEX(Invoer!$BP$38:$BP$57,MATCH(6,Invoer!$BG$38:$BG$57,0))="","",INDEX(Invoer!$BP$38:$BP$57,MATCH(6,Invoer!$BG$38:$BG$57,0))),"") | T12: =IFERROR(IF(INDEX(Invoer!$Q$38:$Q$57,MATCH(6,Invoer!$BG$38:$BG$57,0))="","",INDEX(Invoer!$Q$38:$Q$57,MATCH(6,Invoer!$BG$38:$BG$57,0))),"") | V12: =IFERROR(IF(INDEX(Invoer!$R$38:$R$57,MATCH(6,Invoer!$BG$38:$BG$57,0))="","",INDEX(Invoer!$R$38:$R$57,MATCH(6,Invoer!$BG$38:$BG$57,0))),"") | X12: =IFERROR(IF(N(INDEX(Invoer!$BV$38:$BV$57,MATCH(6,Invoer!$BG$38:$BG$57,0)))=0,"",INDEX(Invoer!$BV$38:$BV$57,MATCH(6,Invoer!$BG$38:$BG$57,0))),"") | Y12: =IFERROR(IF(INDEX(Invoer!$T$38:$T$57,MATCH(6,Invoer!$BG$38:$BG$57,0))="","",INDEX(Invoer!$T$38:$T$57,MATCH(6,Invoer!$BG$38:$BG$57,0))),"") | AA12: =IFERROR(IF(INDEX(Invoer!$U$38:$U$57,MATCH(6,Invoer!$BG$38:$BG$57,0))="","",INDEX(Invoer!$U$38:$U$57,MATCH(6,Invoer!$BG$38:$BG$57,0))),"") | AB12: =IFERROR(IF(INDEX(Invoer!$V$38:$V$57,MATCH(6,Invoer!$BG$38:$BG$57,0))="","",INDEX(Invoer!$V$38:$V$57,MATCH(6,Invoer!$BG$38:$BG$57,0))),"") | AC12: =IFERROR(IF(INDEX(Invoer!$W$38:$W$57,MATCH(6,Invoer!$BG$38:$BG$57,0))="","",INDEX(Invoer!$W$38:$W$57,MATCH(6,Invoer!$BG$38:$BG$57,0))),"") | AE12: =IFERROR(N(INDEX(Invoer!$X$38:$X$57,MATCH(6,Invoer!$BG$38:$BG$57,0))),0) | AF12: =IFERROR(N(INDEX(Invoer!$Y$38:$Y$57,MATCH(6,Invoer!$BG$38:$BG$57,0))),0) | AG12: =IFERROR(N(INDEX(Invoer!$Z$38:$Z$57,MATCH(6,Invoer!$BG$38:$BG$57,0))),0) | AH12: =IFERROR(N(INDEX(Invoer!$AA$38:$AA$57,MATCH(6,Invoer!$BG$38:$BG$57,0))),0) | AI12: =IFERROR(N(INDEX(Invoer!$AB$38:$AB$57,MATCH(6,Invoer!$BG$38:$BG$57,0))),0) | AJ12: =IFERROR(N(INDEX(Invoer!$AC$38:$AC$57,MATCH(6,Invoer!$BG$38:$BG$57,0))),0) | AL12: =IFERROR(N(INDEX(Invoer!$BC$38:$BC$57,MATCH(6,Invoer!$BG$38:$BG$57,0))),0) | AN12: =IFERROR(N(INDEX(Invoer!$BD$38:$BD$57,MATCH(6,Invoer!$BG$38:$BG$57,0))),0) | AP12: =IFERROR(N(INDEX(Invoer!$AD$38:$AD$57,MATCH(6,Invoer!$BG$38:$BG$57,0))),0) | AR12: =(IF(X12<>"",(utwd*(IF(ISNUMBER(AE12),AE12,0))+uttd*(IF(ISNUMBER(AF12),AF12,0))+utsb*(IF(ISNUMBER(AG12),AG12,0))+utrw*(IF(ISNUMBER(AH12),AH12,0))+utd*(IF(ISNUMBER(AI12),AI12,0))+_ut3*(IF(ISNUMBER(AJ12),AJ12,0)) +(IF(ISNUMBER(AP12),AP12,0)))*(IF(Y12="j",1,IF(Y12="m",12,IF(Y12="w",52,IF(Y12="d",365,0)))))/X12,0))*L12 | AT12: =IFERROR(N(INDEX(Invoer!$AJ$38:$AJ$57,MATCH(6,Invoer!$BG$38:$BG$57,0))),0) | AV12: =IFERROR(IF(INDEX(Invoer!$BE$38:$BE$57,MATCH(6,Invoer!$BG$38:$BG$57,0))="","",INDEX(Invoer!$BE$38:$BE$57,MATCH(6,Invoer!$BG$38:$BG$57,0))),"") | AY12: =IF(ISBLANK(AX12),0,(IF(X12<>"",(utwd*(IF(ISNUMBER(AE12),AE12,0))+uttd*(IF(ISNUMBER(AF12),AF12,0))+utsb*(IF(ISNUMBER(AG12),AG12,0))+utrw*(IF(ISNUMBER(AH12),AH12,0))+utd*(IF(ISNUMBER(AI12),AI12,0))+_ut3*(IF(ISNUMBER(AJ12),AJ12,0)) +(IF(ISNUMBER(AP12),AP12,0))),0))*L12) | BA12: =IF(ISBLANK(AZ12),0,(IF(X12<>"",(utwd*(IF(ISNUMBER(AE12),AE12,0))+uttd*(IF(ISNUMBER(AF12),AF12,0))+utsb*(IF(ISNUMBER(AG12),AG12,0))+utrw*(IF(ISNUMBER(AH12),AH12,0))+utd*(IF(ISNUMBER(AI12),AI12,0))+_ut3*(IF(ISNUMBER(AJ12),AJ12,0)) +(IF(ISNUMBER(AP12),AP12,0))),0))*L12) | BC12: =IF(ISBLANK(BB12),0,(IF(X12<>"",(utwd*(IF(ISNUMBER(AE12),AE12,0))+uttd*(IF(ISNUMBER(AF12),AF12,0))+utsb*(IF(ISNUMBER(AG12),AG12,0))+utrw*(IF(ISNUMBER(AH12),AH12,0))+utd*(IF(ISNUMBER(AI12),AI12,0))+_ut3*(IF(ISNUMBER(AJ12),AJ12,0)) +(IF(ISNUMBER(AP12),AP12,0))),0))*L12)
A13: =IFERROR(N(INDEX(Invoer!$B$38:$B$57,MATCH(7,Invoer!$BG$38:$BG$57,0))),0) | B13: =IFERROR(N(INDEX(Invoer!$C$38:$C$57,MATCH(7,Invoer!$BG$38:$BG$57,0))),0) | C13: =IFERROR(N(INDEX(Invoer!$D$38:$D$57,MATCH(7,Invoer!$BG$38:$BG$57,0))),0) | D13: =IFERROR(N(INDEX(Invoer!$E$38:$E$57,MATCH(7,Invoer!$BG$38:$BG$57,0))),0) | E13: =IFERROR(N(INDEX(Invoer!$F$38:$F$57,MATCH(7,Invoer!$BG$38:$BG$57,0))),0) | F13: =IFERROR(N(INDEX(Invoer!$G$38:$G$57,MATCH(7,Invoer!$BG$38:$BG$57,0))),0) | G13: =IFERROR(N(INDEX(Invoer!$H$38:$H$57,MATCH(7,Invoer!$BG$38:$BG$57,0))),0) | H13: =IFERROR(N(INDEX(Invoer!$I$38:$I$57,MATCH(7,Invoer!$BG$38:$BG$57,0))),0) | I13: =IFERROR(N(INDEX(Invoer!$J$38:$J$57,MATCH(7,Invoer!$BG$38:$BG$57,0))),0) | J13: =IFERROR(N(INDEX(Invoer!$K$38:$K$57,MATCH(7,Invoer!$BG$38:$BG$57,0))),0) | K13: =IFERROR(IF(INDEX(Invoer!$L$38:$L$57,MATCH(7,Invoer!$BG$38:$BG$57,0))="","",INDEX(Invoer!$L$38:$L$57,MATCH(7,Invoer!$BG$38:$BG$57,0))),"") | L13: =IFERROR(N(INDEX(Invoer!$M$38:$M$57,MATCH(7,Invoer!$BG$38:$BG$57,0))),0) | M13: =IFERROR(IF(INDEX(Invoer!$BK$38:$BK$57,MATCH(7,Invoer!$BG$38:$BG$57,0))="","",INDEX(Invoer!$BK$38:$BK$57,MATCH(7,Invoer!$BG$38:$BG$57,0))),"") | N13: =IFERROR(IF(INDEX(Invoer!$BL$38:$BL$57,MATCH(7,Invoer!$BG$38:$BG$57,0))="","",INDEX(Invoer!$BL$38:$BL$57,MATCH(7,Invoer!$BG$38:$BG$57,0))),"") | O13: =IFERROR(IF(INDEX(Invoer!$BM$38:$BM$57,MATCH(7,Invoer!$BG$38:$BG$57,0))="","",INDEX(Invoer!$BM$38:$BM$57,MATCH(7,Invoer!$BG$38:$BG$57,0))),"") | P13: =IFERROR(IF(INDEX(Invoer!$BN$38:$BN$57,MATCH(7,Invoer!$BG$38:$BG$57,0))="","",INDEX(Invoer!$BN$38:$BN$57,MATCH(7,Invoer!$BG$38:$BG$57,0))),"") | Q13: =IFERROR(IF(INDEX(Invoer!$BO$38:$BO$57,MATCH(7,Invoer!$BG$38:$BG$57,0))="","",INDEX(Invoer!$BO$38:$BO$57,MATCH(7,Invoer!$BG$38:$BG$57,0))),"") | R13: =IFERROR(IF(INDEX(Invoer!$BP$38:$BP$57,MATCH(7,Invoer!$BG$38:$BG$57,0))="","",INDEX(Invoer!$BP$38:$BP$57,MATCH(7,Invoer!$BG$38:$BG$57,0))),"") | T13: =IFERROR(IF(INDEX(Invoer!$Q$38:$Q$57,MATCH(7,Invoer!$BG$38:$BG$57,0))="","",INDEX(Invoer!$Q$38:$Q$57,MATCH(7,Invoer!$BG$38:$BG$57,0))),"") | V13: =IFERROR(IF(INDEX(Invoer!$R$38:$R$57,MATCH(7,Invoer!$BG$38:$BG$57,0))="","",INDEX(Invoer!$R$38:$R$57,MATCH(7,Invoer!$BG$38:$BG$57,0))),"") | X13: =IFERROR(IF(N(INDEX(Invoer!$BV$38:$BV$57,MATCH(7,Invoer!$BG$38:$BG$57,0)))=0,"",INDEX(Invoer!$BV$38:$BV$57,MATCH(7,Invoer!$BG$38:$BG$57,0))),"") | Y13: =IFERROR(IF(INDEX(Invoer!$T$38:$T$57,MATCH(7,Invoer!$BG$38:$BG$57,0))="","",INDEX(Invoer!$T$38:$T$57,MATCH(7,Invoer!$BG$38:$BG$57,0))),"") | AA13: =IFERROR(IF(INDEX(Invoer!$U$38:$U$57,MATCH(7,Invoer!$BG$38:$BG$57,0))="","",INDEX(Invoer!$U$38:$U$57,MATCH(7,Invoer!$BG$38:$BG$57,0))),"") | AB13: =IFERROR(IF(INDEX(Invoer!$V$38:$V$57,MATCH(7,Invoer!$BG$38:$BG$57,0))="","",INDEX(Invoer!$V$38:$V$57,MATCH(7,Invoer!$BG$38:$BG$57,0))),"") | AC13: =IFERROR(IF(INDEX(Invoer!$W$38:$W$57,MATCH(7,Invoer!$BG$38:$BG$57,0))="","",INDEX(Invoer!$W$38:$W$57,MATCH(7,Invoer!$BG$38:$BG$57,0))),"") | AE13: =IFERROR(N(INDEX(Invoer!$X$38:$X$57,MATCH(7,Invoer!$BG$38:$BG$57,0))),0) | AF13: =IFERROR(N(INDEX(Invoer!$Y$38:$Y$57,MATCH(7,Invoer!$BG$38:$BG$57,0))),0) | AG13: =IFERROR(N(INDEX(Invoer!$Z$38:$Z$57,MATCH(7,Invoer!$BG$38:$BG$57,0))),0) | AH13: =IFERROR(N(INDEX(Invoer!$AA$38:$AA$57,MATCH(7,Invoer!$BG$38:$BG$57,0))),0) | AI13: =IFERROR(N(INDEX(Invoer!$AB$38:$AB$57,MATCH(7,Invoer!$BG$38:$BG$57,0))),0) | AJ13: =IFERROR(N(INDEX(Invoer!$AC$38:$AC$57,MATCH(7,Invoer!$BG$38:$BG$57,0))),0) | AL13: =IFERROR(N(INDEX(Invoer!$BC$38:$BC$57,MATCH(7,Invoer!$BG$38:$BG$57,0))),0) | AN13: =IFERROR(N(INDEX(Invoer!$BD$38:$BD$57,MATCH(7,Invoer!$BG$38:$BG$57,0))),0) | AP13: =IFERROR(N(INDEX(Invoer!$AD$38:$AD$57,MATCH(7,Invoer!$BG$38:$BG$57,0))),0) | AR13: =(IF(X13<>"",(utwd*(IF(ISNUMBER(AE13),AE13,0))+uttd*(IF(ISNUMBER(AF13),AF13,0))+utsb*(IF(ISNUMBER(AG13),AG13,0))+utrw*(IF(ISNUMBER(AH13),AH13,0))+utd*(IF(ISNUMBER(AI13),AI13,0))+_ut3*(IF(ISNUMBER(AJ13),AJ13,0)) +(IF(ISNUMBER(AP13),AP13,0)))*(IF(Y13="j",1,IF(Y13="m",12,IF(Y13="w",52,IF(Y13="d",365,0)))))/X13,0))*L13 | AT13: =IFERROR(N(INDEX(Invoer!$AJ$38:$AJ$57,MATCH(7,Invoer!$BG$38:$BG$57,0))),0) | AV13: =IFERROR(IF(INDEX(Invoer!$BE$38:$BE$57,MATCH(7,Invoer!$BG$38:$BG$57,0))="","",INDEX(Invoer!$BE$38:$BE$57,MATCH(7,Invoer!$BG$38:$BG$57,0))),"") | AY13: =IF(ISBLANK(AX13),0,(IF(X13<>"",(utwd*(IF(ISNUMBER(AE13),AE13,0))+uttd*(IF(ISNUMBER(AF13),AF13,0))+utsb*(IF(ISNUMBER(AG13),AG13,0))+utrw*(IF(ISNUMBER(AH13),AH13,0))+utd*(IF(ISNUMBER(AI13),AI13,0))+_ut3*(IF(ISNUMBER(AJ13),AJ13,0)) +(IF(ISNUMBER(AP13),AP13,0))),0))*L13) | BA13: =IF(ISBLANK(AZ13),0,(IF(X13<>"",(utwd*(IF(ISNUMBER(AE13),AE13,0))+uttd*(IF(ISNUMBER(AF13),AF13,0))+utsb*(IF(ISNUMBER(AG13),AG13,0))+utrw*(IF(ISNUMBER(AH13),AH13,0))+utd*(IF(ISNUMBER(AI13),AI13,0))+_ut3*(IF(ISNUMBER(AJ13),AJ13,0)) +(IF(ISNUMBER(AP13),AP13,0))),0))*L13) | BC13: =IF(ISBLANK(BB13),0,(IF(X13<>"",(utwd*(IF(ISNUMBER(AE13),AE13,0))+uttd*(IF(ISNUMBER(AF13),AF13,0))+utsb*(IF(ISNUMBER(AG13),AG13,0))+utrw*(IF(ISNUMBER(AH13),AH13,0))+utd*(IF(ISNUMBER(AI13),AI13,0))+_ut3*(IF(ISNUMBER(AJ13),AJ13,0)) +(IF(ISNUMBER(AP13),AP13,0))),0))*L13)
A14: =IFERROR(N(INDEX(Invoer!$B$38:$B$57,MATCH(8,Invoer!$BG$38:$BG$57,0))),0) | B14: =IFERROR(N(INDEX(Invoer!$C$38:$C$57,MATCH(8,Invoer!$BG$38:$BG$57,0))),0) | C14: =IFERROR(N(INDEX(Invoer!$D$38:$D$57,MATCH(8,Invoer!$BG$38:$BG$57,0))),0) | D14: =IFERROR(N(INDEX(Invoer!$E$38:$E$57,MATCH(8,Invoer!$BG$38:$BG$57,0))),0) | E14: =IFERROR(N(INDEX(Invoer!$F$38:$F$57,MATCH(8,Invoer!$BG$38:$BG$57,0))),0) | F14: =IFERROR(N(INDEX(Invoer!$G$38:$G$57,MATCH(8,Invoer!$BG$38:$BG$57,0))),0) | G14: =IFERROR(N(INDEX(Invoer!$H$38:$H$57,MATCH(8,Invoer!$BG$38:$BG$57,0))),0) | H14: =IFERROR(N(INDEX(Invoer!$I$38:$I$57,MATCH(8,Invoer!$BG$38:$BG$57,0))),0) | I14: =IFERROR(N(INDEX(Invoer!$J$38:$J$57,MATCH(8,Invoer!$BG$38:$BG$57,0))),0) | J14: =IFERROR(N(INDEX(Invoer!$K$38:$K$57,MATCH(8,Invoer!$BG$38:$BG$57,0))),0) | K14: =IFERROR(IF(INDEX(Invoer!$L$38:$L$57,MATCH(8,Invoer!$BG$38:$BG$57,0))="","",INDEX(Invoer!$L$38:$L$57,MATCH(8,Invoer!$BG$38:$BG$57,0))),"") | L14: =IFERROR(N(INDEX(Invoer!$M$38:$M$57,MATCH(8,Invoer!$BG$38:$BG$57,0))),0) | M14: =IFERROR(IF(INDEX(Invoer!$BK$38:$BK$57,MATCH(8,Invoer!$BG$38:$BG$57,0))="","",INDEX(Invoer!$BK$38:$BK$57,MATCH(8,Invoer!$BG$38:$BG$57,0))),"") | N14: =IFERROR(IF(INDEX(Invoer!$BL$38:$BL$57,MATCH(8,Invoer!$BG$38:$BG$57,0))="","",INDEX(Invoer!$BL$38:$BL$57,MATCH(8,Invoer!$BG$38:$BG$57,0))),"") | O14: =IFERROR(IF(INDEX(Invoer!$BM$38:$BM$57,MATCH(8,Invoer!$BG$38:$BG$57,0))="","",INDEX(Invoer!$BM$38:$BM$57,MATCH(8,Invoer!$BG$38:$BG$57,0))),"") | P14: =IFERROR(IF(INDEX(Invoer!$BN$38:$BN$57,MATCH(8,Invoer!$BG$38:$BG$57,0))="","",INDEX(Invoer!$BN$38:$BN$57,MATCH(8,Invoer!$BG$38:$BG$57,0))),"") | Q14: =IFERROR(IF(INDEX(Invoer!$BO$38:$BO$57,MATCH(8,Invoer!$BG$38:$BG$57,0))="","",INDEX(Invoer!$BO$38:$BO$57,MATCH(8,Invoer!$BG$38:$BG$57,0))),"") | R14: =IFERROR(IF(INDEX(Invoer!$BP$38:$BP$57,MATCH(8,Invoer!$BG$38:$BG$57,0))="","",INDEX(Invoer!$BP$38:$BP$57,MATCH(8,Invoer!$BG$38:$BG$57,0))),"") | T14: =IFERROR(IF(INDEX(Invoer!$Q$38:$Q$57,MATCH(8,Invoer!$BG$38:$BG$57,0))="","",INDEX(Invoer!$Q$38:$Q$57,MATCH(8,Invoer!$BG$38:$BG$57,0))),"") | V14: =IFERROR(IF(INDEX(Invoer!$R$38:$R$57,MATCH(8,Invoer!$BG$38:$BG$57,0))="","",INDEX(Invoer!$R$38:$R$57,MATCH(8,Invoer!$BG$38:$BG$57,0))),"") | X14: =IFERROR(IF(N(INDEX(Invoer!$BV$38:$BV$57,MATCH(8,Invoer!$BG$38:$BG$57,0)))=0,"",INDEX(Invoer!$BV$38:$BV$57,MATCH(8,Invoer!$BG$38:$BG$57,0))),"") | Y14: =IFERROR(IF(INDEX(Invoer!$T$38:$T$57,MATCH(8,Invoer!$BG$38:$BG$57,0))="","",INDEX(Invoer!$T$38:$T$57,MATCH(8,Invoer!$BG$38:$BG$57,0))),"") | AA14: =IFERROR(IF(INDEX(Invoer!$U$38:$U$57,MATCH(8,Invoer!$BG$38:$BG$57,0))="","",INDEX(Invoer!$U$38:$U$57,MATCH(8,Invoer!$BG$38:$BG$57,0))),"") | AB14: =IFERROR(IF(INDEX(Invoer!$V$38:$V$57,MATCH(8,Invoer!$BG$38:$BG$57,0))="","",INDEX(Invoer!$V$38:$V$57,MATCH(8,Invoer!$BG$38:$BG$57,0))),"") | AC14: =IFERROR(IF(INDEX(Invoer!$W$38:$W$57,MATCH(8,Invoer!$BG$38:$BG$57,0))="","",INDEX(Invoer!$W$38:$W$57,MATCH(8,Invoer!$BG$38:$BG$57,0))),"") | AE14: =IFERROR(N(INDEX(Invoer!$X$38:$X$57,MATCH(8,Invoer!$BG$38:$BG$57,0))),0) | AF14: =IFERROR(N(INDEX(Invoer!$Y$38:$Y$57,MATCH(8,Invoer!$BG$38:$BG$57,0))),0) | AG14: =IFERROR(N(INDEX(Invoer!$Z$38:$Z$57,MATCH(8,Invoer!$BG$38:$BG$57,0))),0) | AH14: =IFERROR(N(INDEX(Invoer!$AA$38:$AA$57,MATCH(8,Invoer!$BG$38:$BG$57,0))),0) | AI14: =IFERROR(N(INDEX(Invoer!$AB$38:$AB$57,MATCH(8,Invoer!$BG$38:$BG$57,0))),0) | AJ14: =IFERROR(N(INDEX(Invoer!$AC$38:$AC$57,MATCH(8,Invoer!$BG$38:$BG$57,0))),0) | AL14: =IFERROR(N(INDEX(Invoer!$BC$38:$BC$57,MATCH(8,Invoer!$BG$38:$BG$57,0))),0) | AN14: =IFERROR(N(INDEX(Invoer!$BD$38:$BD$57,MATCH(8,Invoer!$BG$38:$BG$57,0))),0) | AP14: =IFERROR(N(INDEX(Invoer!$AD$38:$AD$57,MATCH(8,Invoer!$BG$38:$BG$57,0))),0) | AR14: =(IF(X14<>"",(utwd*(IF(ISNUMBER(AE14),AE14,0))+uttd*(IF(ISNUMBER(AF14),AF14,0))+utsb*(IF(ISNUMBER(AG14),AG14,0))+utrw*(IF(ISNUMBER(AH14),AH14,0))+utd*(IF(ISNUMBER(AI14),AI14,0))+_ut3*(IF(ISNUMBER(AJ14),AJ14,0)) +(IF(ISNUMBER(AP14),AP14,0)))*(IF(Y14="j",1,IF(Y14="m",12,IF(Y14="w",52,IF(Y14="d",365,0)))))/X14,0))*L14 | AT14: =IFERROR(N(INDEX(Invoer!$AJ$38:$AJ$57,MATCH(8,Invoer!$BG$38:$BG$57,0))),0) | AV14: =IFERROR(IF(INDEX(Invoer!$BE$38:$BE$57,MATCH(8,Invoer!$BG$38:$BG$57,0))="","",INDEX(Invoer!$BE$38:$BE$57,MATCH(8,Invoer!$BG$38:$BG$57,0))),"") | AY14: =IF(ISBLANK(AX14),0,(IF(X14<>"",(utwd*(IF(ISNUMBER(AE14),AE14,0))+uttd*(IF(ISNUMBER(AF14),AF14,0))+utsb*(IF(ISNUMBER(AG14),AG14,0))+utrw*(IF(ISNUMBER(AH14),AH14,0))+utd*(IF(ISNUMBER(AI14),AI14,0))+_ut3*(IF(ISNUMBER(AJ14),AJ14,0)) +(IF(ISNUMBER(AP14),AP14,0))),0))*L14) | BA14: =IF(ISBLANK(AZ14),0,(IF(X14<>"",(utwd*(IF(ISNUMBER(AE14),AE14,0))+uttd*(IF(ISNUMBER(AF14),AF14,0))+utsb*(IF(ISNUMBER(AG14),AG14,0))+utrw*(IF(ISNUMBER(AH14),AH14,0))+utd*(IF(ISNUMBER(AI14),AI14,0))+_ut3*(IF(ISNUMBER(AJ14),AJ14,0)) +(IF(ISNUMBER(AP14),AP14,0))),0))*L14) | BC14: =IF(ISBLANK(BB14),0,(IF(X14<>"",(utwd*(IF(ISNUMBER(AE14),AE14,0))+uttd*(IF(ISNUMBER(AF14),AF14,0))+utsb*(IF(ISNUMBER(AG14),AG14,0))+utrw*(IF(ISNUMBER(AH14),AH14,0))+utd*(IF(ISNUMBER(AI14),AI14,0))+_ut3*(IF(ISNUMBER(AJ14),AJ14,0)) +(IF(ISNUMBER(AP14),AP14,0))),0))*L14)
