Workbook

Sheet Toelichting
B2: Delta tabel gebrekgroepen (gebrekgroep)
B3: Overzicht van gebrekgroepen met hun gekoppelde gebreken en de wijzigingen (oud → nieuw), overgenomen uit de PDF.
B5: Bron | C5: delta-tabel-gebrekgroep-.pdf (6 pagina’s)
B7: Legenda
B8: Groen vetgedrukt | C8: Nieuwe waarde / nieuw gekoppeld → mutatie “Toegevoegd”
B9: Rood doorgehaald | C9: Oude waarde / niet langer gekoppeld → mutatie “Vervallen”
B10: Oranje cursief | C10: Gewijzigd (gebrek hernoemd) → mutatie “Gewijzigd”
B11: Zonder opmaak | C11: Ongewijzigd → mutatie “Ongewijzigd”
B12: Gele markering | C12: Cel gemarkeerd in de bron (tabblad “Delta tabel”)
B14: Samenvatting
B15: Aantal gebrekgroepen | C15: =COUNTA(Gebrekgroepen!$A$2:$A$16) -> 15
B16: waarvan nieuw | C16: =COUNTIF(Gebrekgroepen!$B$2:$B$16,"Nieuw") -> 0
B17: waarvan vervallen | C17: =COUNTIF(Gebrekgroepen!$B$2:$B$16,"Vervallen") -> 0
B18: waarvan hernoemd | C18: =COUNTIF(Gebrekgroepen!$B$2:$B$16,"Hernoemd") -> 0
B19: Gebrekgroepen met wijzigingen (totaal) | C19: =COUNTIF(Gebrekgroepen!$I$2:$I$16,"Gewijzigd")+COUNTIF(Gebrekgroepen!$I$2:$I$16,"Nieuw")+COUNTIF(Gebrekgroepen!$I$2:$I$16,"Vervallen") -> 7
B20: Koppelingen gebrek (totaal regels) | C20: =COUNTA(Gebreken!$A$2:$A$167) -> 166
B21: Koppelingen gebrek – ongewijzigd | C21: =COUNTIF(Gebreken!$D$2:$D$167,"Ongewijzigd") -> 118
B22: Koppelingen gebrek – toegevoegd | C22: =COUNTIF(Gebreken!$D$2:$D$167,"Toegevoegd") -> 12
B23: Koppelingen gebrek – vervallen | C23: =COUNTIF(Gebreken!$D$2:$D$167,"Vervallen") -> 28
B24: Koppelingen gebrek – gewijzigd (gebrek hernoemd) | C24: =COUNTIF(Gebreken!$D$2:$D$167,"Gewijzigd") -> 8
B25: Totaal regels in tabblad Wijzigingen | C25: =COUNTA(Wijzigingen!$A$2:$A$49) -> 48
B27: Tabbladen
B28: Gebrekgroepen | C28: Eén regel per gebrekgroep met status, de gekoppelde gebreken en tellingen (formules).
B29: Gebreken | C29: Eén regel per gebrekgroep × gebrek met mutatie (Excel-tabel, filterbaar).
B30: Wijzigingen | C30: Alleen de gewijzigde regels.
B31: Delta tabel | C31: Getrouwe weergave van de oorspronkelijke delta tabel (kolommen Oud / Nieuw, met opmaak).
B33: Opmerkingen bij de conversie
B34: • Deze tabel bevat alleen de naam van de gebrekgroep en de gekoppelde gebreken; er zijn geen andere kenmerken in de bron.
B35: • De gebrekgroepen zelf zijn allemaal ongewijzigd: er komen er geen bij en er vervallen er geen. Alleen de koppelingen met gebreken veranderen.
B36: • Oranje regels zijn gebreken die zijn hernoemd; de koppeling met de gebrekgroep blijft dan bestaan.
B37: • De gebrekgroep “Conservering” heeft in de bron geen gekoppelde gebreken.
B38: • Tekens met verkeerde codering in de bron (bijv. “Ã«”) zijn hersteld (“ë”); letterlijke codes “\r\n” in teksten zijn verwijderd.
B39: • Tekst is verder 1-op-1 overgenomen; eventuele type- of spelfouten uit de bron zijn niet gecorrigeerd.

Sheet Gebrekgroepen
A1: Gebrekgroep | B1: Groepstatus | C1: Naam (vorige versie) | D1: Gebreken (actueel) | E1: Gebreken (oud) | F1: Gebreken (nieuw) | G1: Toegevoegd | H1: Vervallen | I1: Status
A2: Beschadiging | B2: Bestaand | D2: Afbrokkelen, Afdichting, defect, Afschuiving, Oeverafslag, Grasmat, beschadigd, Breuk, Deformatie, kritiek, Groeven, Houtrot, Krassen, Ontgronding, Rafeling, Scheur, niet constructief, Scheur, constructief, Beschermlaag, defect, Uitspoeling, Verankering, defect, Vergraving, Verpoederen, Verzakking, Scheefstand, Rafeling (ZOAB), Verwering, Verzanding, Voegvulling, defect, Randschade, Dakgrind, ingezakt, Kieren, Losliggend, Aansluiting, onjuist, Breuk/instorting, riool, Oppervlakteschade, Verbinding, verplaatst, Lining, defect, Materiaal, poreus, Wortelingroei, Bezinksel, Grondindringing, Obstakels, Infiltratie, Scheurvorming, Deformatie, niet kritiek, Onthechting, Delaminatie, Vervorming, Desintegratie, Slijtage, mechanisch, Aansluiting, defect, Verpulveren, Verruiging, Windworp, Omgevallen, Aansluiting, onvoldoende, Erosie, Gaten | E2: =COUNTIFS(Gebreken!$A$2:$A$167,$A2,Gebreken!$B$2:$B$167,"?*") -> 54 | F2: =COUNTIFS(Gebreken!$A$2:$A$167,$A2,Gebreken!$C$2:$C$167,"?*") -> 55 | G2: =COUNTIFS(Gebreken!$A$2:$A$167,$A2,Gebreken!$D$2:$D$167,"Toegevoegd") -> 5 | H2: =COUNTIFS(Gebreken!$A$2:$A$167,$A2,Gebreken!$D$2:$D$167,"Vervallen") -> 4 | I2: =IF(B2="Nieuw","Nieuw",IF(B2="Vervallen","Vervallen",IF(COUNTIF(Wijzigingen!$A$2:$A$49,$A2)>0,"Gewijzigd","Ongewijzigd"))) -> Gewijzigd
A3: Bevestiging | B3: Bestaand | D3: Bevestiging, onjuist, Bevestiging, ontbreekt, Bevestiging, defect | E3: =COUNTIFS(Gebreken!$A$2:$A$167,$A3,Gebreken!$B$2:$B$167,"?*") -> 3 | F3: =COUNTIFS(Gebreken!$A$2:$A$167,$A3,Gebreken!$C$2:$C$167,"?*") -> 3 | G3: =COUNTIFS(Gebreken!$A$2:$A$167,$A3,Gebreken!$D$2:$D$167,"Toegevoegd") -> 0 | H3: =COUNTIFS(Gebreken!$A$2:$A$167,$A3,Gebreken!$D$2:$D$167,"Vervallen") -> 0 | I3: =IF(B3="Nieuw","Nieuw",IF(B3="Vervallen","Vervallen",IF(COUNTIF(Wijzigingen!$A$2:$A$49,$A3)>0,"Gewijzigd","Ongewijzigd"))) -> Ongewijzigd
A4: Codering | B4: Bestaand | D4: Codering, onjuist | E4: =COUNTIFS(Gebreken!$A$2:$A$167,$A4,Gebreken!$B$2:$B$167,"?*") -> 1 | F4: =COUNTIFS(Gebreken!$A$2:$A$167,$A4,Gebreken!$C$2:$C$167,"?*") -> 1 | G4: =COUNTIFS(Gebreken!$A$2:$A$167,$A4,Gebreken!$D$2:$D$167,"Toegevoegd") -> 0 | H4: =COUNTIFS(Gebreken!$A$2:$A$167,$A4,Gebreken!$D$2:$D$167,"Vervallen") -> 0 | I4: =IF(B4="Nieuw","Nieuw",IF(B4="Vervallen","Vervallen",IF(COUNTIF(Wijzigingen!$A$2:$A$49,$A4)>0,"Gewijzigd","Ongewijzigd"))) -> Ongewijzigd
A5: Conservering | B5: Bestaand | E5: =COUNTIFS(Gebreken!$A$2:$A$167,$A5,Gebreken!$B$2:$B$167,"?*") -> 0 | F5: =COUNTIFS(Gebreken!$A$2:$A$167,$A5,Gebreken!$C$2:$C$167,"?*") -> 0 | G5: =COUNTIFS(Gebreken!$A$2:$A$167,$A5,Gebreken!$D$2:$D$167,"Toegevoegd") -> 0 | H5: =COUNTIFS(Gebreken!$A$2:$A$167,$A5,Gebreken!$D$2:$D$167,"Vervallen") -> 0 | I5: =IF(B5="Nieuw","Nieuw",IF(B5="Vervallen","Vervallen",IF(COUNTIF(Wijzigingen!$A$2:$A$49,$A5)>0,"Gewijzigd","Ongewijzigd"))) -> Ongewijzigd
A6: Corrosie | B6: Bestaand | D6: Corrosie, uniform, Putcorrosie, Spleetcorrosie, Wapeningscorrosie | E6: =COUNTIFS(Gebreken!$A$2:$A$167,$A6,Gebreken!$B$2:$B$167,"?*") -> 4 | F6: =COUNTIFS(Gebreken!$A$2:$A$167,$A6,Gebreken!$C$2:$C$167,"?*") -> 4 | G6: =COUNTIFS(Gebreken!$A$2:$A$167,$A6,Gebreken!$D$2:$D$167,"Toegevoegd") -> 0 | H6: =COUNTIFS(Gebreken!$A$2:$A$167,$A6,Gebreken!$D$2:$D$167,"Vervallen") -> 0 | I6: =IF(B6="Nieuw","Nieuw",IF(B6="Vervallen","Vervallen",IF(COUNTIF(Wijzigingen!$A$2:$A$49,$A6)>0,"Gewijzigd","Ongewijzigd"))) -> Ongewijzigd
A7: Documentatie | B7: Bestaand | D7: Documentatie, onjuist | E7: =COUNTIFS(Gebreken!$A$2:$A$167,$A7,Gebreken!$B$2:$B$167,"?*") -> 1 | F7: =COUNTIFS(Gebreken!$A$2:$A$167,$A7,Gebreken!$C$2:$C$167,"?*") -> 1 | G7: =COUNTIFS(Gebreken!$A$2:$A$167,$A7,Gebreken!$D$2:$D$167,"Toegevoegd") -> 0 | H7: =COUNTIFS(Gebreken!$A$2:$A$167,$A7,Gebreken!$D$2:$D$167,"Vervallen") -> 0 | I7: =IF(B7="Nieuw","Nieuw",IF(B7="Vervallen","Vervallen",IF(COUNTIF(Wijzigingen!$A$2:$A$49,$A7)>0,"Gewijzigd","Ongewijzigd"))) -> Ongewijzigd
A8: Functionaliteit | B8: Bestaand | D8: Beschermingsgraad, onvoldoende, Functie, verminderd, Functie, afwezig, Servicetermijn, ten einde, Instelling, foutief, Kortsluitvastheid, onvoldoende, Markering, onjuist, Onderdeel, ontbreekt, Diepte, onvoldoende, Smering, onvoldoende, Trilling, overmatig, Warmte-ontwikkeling, overmatig, Verspreidingsweerstand, onjuist, Verkeerstekens, onvoldoende, Capaciteit, verminderd, Inlaat, instekend, Vloeistofpeil, onjuist, Begroeiing, ongewenst, Verdwenen | E8: =COUNTIFS(Gebreken!$A$2:$A$167,$A8,Gebreken!$B$2:$B$167,"?*") -> 17 | F8: =COUNTIFS(Gebreken!$A$2:$A$167,$A8,Gebreken!$C$2:$C$167,"?*") -> 19 | G8: =COUNTIFS(Gebreken!$A$2:$A$167,$A8,Gebreken!$D$2:$D$167,"Toegevoegd") -> 2 | H8: =COUNTIFS(Gebreken!$A$2:$A$167,$A8,Gebreken!$D$2:$D$167,"Vervallen") -> 0 | I8: =IF(B8="Nieuw","Nieuw",IF(B8="Vervallen","Vervallen",IF(COUNTIF(Wijzigingen!$A$2:$A$49,$A8)>0,"Gewijzigd","Ongewijzigd"))) -> Gewijzigd
A9: Groei, ontwikkeling | B9: Bestaand | D9: Biotoop, afwijkend, Bladverkleuring, Scheutlengte-ontwikkeling, Wondreactie, Bloeiontwikkeling, Stamontwikkeling | E9: =COUNTIFS(Gebreken!$A$2:$A$167,$A9,Gebreken!$B$2:$B$167,"?*") -> 17 | F9: =COUNTIFS(Gebreken!$A$2:$A$167,$A9,Gebreken!$C$2:$C$167,"?*") -> 6 | G9: =COUNTIFS(Gebreken!$A$2:$A$167,$A9,Gebreken!$D$2:$D$167,"Toegevoegd") -> 0 | H9: =COUNTIFS(Gebreken!$A$2:$A$167,$A9,Gebreken!$D$2:$D$167,"Vervallen") -> 11 | I9: =IF(B9="Nieuw","Nieuw",IF(B9="Vervallen","Vervallen",IF(COUNTIF(Wijzigingen!$A$2:$A$49,$A9)>0,"Gewijzigd","Ongewijzigd"))) -> Gewijzigd
A10: Groen | B10: Bestaand | D10: Afsterving, Houtweefselschade, Toplaag, dichtgeslibd, Dichtgroei, boomopslag, Vergrassing, Verhouting, Verlanding, Vermossing, Verstuiving, Bedekkingsgraad, Schade, mechanisch, Draagkracht bodem, onvoldoende, Slijtage, sportvelden, Bladontwikkeling, Groeiontwikkeling, Afdekking, ongewenst, Soortenrijkdom, onvoldoende | E10: =COUNTIFS(Gebreken!$A$2:$A$167,$A10,Gebreken!$B$2:$B$167,"?*") -> 21 | F10: =COUNTIFS(Gebreken!$A$2:$A$167,$A10,Gebreken!$C$2:$C$167,"?*") -> 17 | G10: =COUNTIFS(Gebreken!$A$2:$A$167,$A10,Gebreken!$D$2:$D$167,"Toegevoegd") -> 3 | H10: =COUNTIFS(Gebreken!$A$2:$A$167,$A10,Gebreken!$D$2:$D$167,"Vervallen") -> 7 | I10: =IF(B10="Nieuw","Nieuw",IF(B10="Vervallen","Vervallen",IF(COUNTIF(Wijzigingen!$A$2:$A$49,$A10)>0,"Gewijzigd","Ongewijzigd"))) -> Gewijzigd
A11: Leeftijd, veroudering | B11: Bestaand | D11: Theoretische levensduur, 100%, Theoretische levensduur, tussen 50% en 75%, Theoretische levensduur, ouder dan 75% | E11: =COUNTIFS(Gebreken!$A$2:$A$167,$A11,Gebreken!$B$2:$B$167,"?*") -> 3 | F11: =COUNTIFS(Gebreken!$A$2:$A$167,$A11,Gebreken!$C$2:$C$167,"?*") -> 3 | G11: =COUNTIFS(Gebreken!$A$2:$A$167,$A11,Gebreken!$D$2:$D$167,"Toegevoegd") -> 0 | H11: =COUNTIFS(Gebreken!$A$2:$A$167,$A11,Gebreken!$D$2:$D$167,"Vervallen") -> 0 | I11: =IF(B11="Nieuw","Nieuw",IF(B11="Vervallen","Vervallen",IF(COUNTIF(Wijzigingen!$A$2:$A$49,$A11)>0,"Gewijzigd","Ongewijzigd"))) -> Ongewijzigd
A12: Orde, netheid | B12: Bestaand | D12: Graffity, Onkruidgroei, Organische stof, overlast, Verstopping, Vervuiling, Afzetting, aangehecht, Aangroei, Afzetting, bezonken | E12: =COUNTIFS(Gebreken!$A$2:$A$167,$A12,Gebreken!$B$2:$B$167,"?*") -> 9 | F12: =COUNTIFS(Gebreken!$A$2:$A$167,$A12,Gebreken!$C$2:$C$167,"?*") -> 8 | G12: =COUNTIFS(Gebreken!$A$2:$A$167,$A12,Gebreken!$D$2:$D$167,"Toegevoegd") -> 0 | H12: =COUNTIFS(Gebreken!$A$2:$A$167,$A12,Gebreken!$D$2:$D$167,"Vervallen") -> 1 | I12: =IF(B12="Nieuw","Nieuw",IF(B12="Vervallen","Vervallen",IF(COUNTIF(Wijzigingen!$A$2:$A$49,$A12)>0,"Gewijzigd","Ongewijzigd"))) -> Gewijzigd
A13: Veiligheid & Wet en regelgeving | B13: Bestaand | D13: Stroefheid, Wet & regelgeving, voldoet niet | E13: =COUNTIFS(Gebreken!$A$2:$A$167,$A13,Gebreken!$B$2:$B$167,"?*") -> 4 | F13: =COUNTIFS(Gebreken!$A$2:$A$167,$A13,Gebreken!$C$2:$C$167,"?*") -> 2 | G13: =COUNTIFS(Gebreken!$A$2:$A$167,$A13,Gebreken!$D$2:$D$167,"Toegevoegd") -> 0 | H13: =COUNTIFS(Gebreken!$A$2:$A$167,$A13,Gebreken!$D$2:$D$167,"Vervallen") -> 2 | I13: =IF(B13="Nieuw","Nieuw",IF(B13="Vervallen","Vervallen",IF(COUNTIF(Wijzigingen!$A$2:$A$49,$A13)>0,"Gewijzigd","Ongewijzigd"))) -> Gewijzigd
A14: Vlakheid | B14: Bestaand | D14: Afschot, foutief, Boomwortelopgroei, Dwarsonvlakheid, Langsonvlakheid, Oneffenheden, Opbolling, Plasvorming, Spoorvorming, Voegwijdte, onjuist, Zetting, Spoordiepte, Comfort, fietspad | E14: =COUNTIFS(Gebreken!$A$2:$A$167,$A14,Gebreken!$B$2:$B$167,"?*") -> 12 | F14: =COUNTIFS(Gebreken!$A$2:$A$167,$A14,Gebreken!$C$2:$C$167,"?*") -> 12 | G14: =COUNTIFS(Gebreken!$A$2:$A$167,$A14,Gebreken!$D$2:$D$167,"Toegevoegd") -> 0 | H14: =COUNTIFS(Gebreken!$A$2:$A$167,$A14,Gebreken!$D$2:$D$167,"Vervallen") -> 0 | I14: =IF(B14="Nieuw","Nieuw",IF(B14="Vervallen","Vervallen",IF(COUNTIF(Wijzigingen!$A$2:$A$49,$A14)>0,"Gewijzigd","Ongewijzigd"))) -> Ongewijzigd
A15: Vocht, water | B15: Bestaand | D15: Kwelplek, Verweking, Wellen (zandmeevoerend) | E15: =COUNTIFS(Gebreken!$A$2:$A$167,$A15,Gebreken!$B$2:$B$167,"?*") -> 3 | F15: =COUNTIFS(Gebreken!$A$2:$A$167,$A15,Gebreken!$C$2:$C$167,"?*") -> 3 | G15: =COUNTIFS(Gebreken!$A$2:$A$167,$A15,Gebreken!$D$2:$D$167,"Toegevoegd") -> 0 | H15: =COUNTIFS(Gebreken!$A$2:$A$167,$A15,Gebreken!$D$2:$D$167,"Vervallen") -> 0 | I15: =IF(B15="Nieuw","Nieuw",IF(B15="Vervallen","Vervallen",IF(COUNTIF(Wijzigingen!$A$2:$A$49,$A15)>0,"Gewijzigd","Ongewijzigd"))) -> Ongewijzigd
A16: Ziekte, aandoening | B16: Bestaand | D16: Leemgehalte, onjuist, Verzuring, Blauwalgontwikkeling, Aantasting | E16: =COUNTIFS(Gebreken!$A$2:$A$167,$A16,Gebreken!$B$2:$B$167,"?*") -> 5 | F16: =COUNTIFS(Gebreken!$A$2:$A$167,$A16,Gebreken!$C$2:$C$167,"?*") -> 4 | G16: =COUNTIFS(Gebreken!$A$2:$A$167,$A16,Gebreken!$D$2:$D$167,"Toegevoegd") -> 2 | H16: =COUNTIFS(Gebreken!$A$2:$A$167,$A16,Gebreken!$D$2:$D$167,"Vervallen") -> 3 | I16: =IF(B16="Nieuw","Nieuw",IF(B16="Vervallen","Vervallen",IF(COUNTIF(Wijzigingen!$A$2:$A$49,$A16)>0,"Gewijzigd","Ongewijzigd"))) -> Gewijzigd

Sheet Gebreken
A1: Gebrekgroep | B1: Gebrek (oud) | C1: Gebrek (nieuw) | D1: Mutatie
A2: Beschadiging | B2: Afbrokkelen | C2: Afbrokkelen | D2: Ongewijzigd
A3: Beschadiging | B3: Afdichting, defect | C3: Afdichting, defect | D3: Ongewijzigd
A4: Beschadiging | B4: Afschuiving | C4: Afschuiving | D4: Ongewijzigd
A5: Beschadiging | B5: Oeverafslag | C5: Oeverafslag | D5: Ongewijzigd
A6: Beschadiging | B6: Grasmat, beschadigd | C6: Grasmat, beschadigd | D6: Ongewijzigd
A7: Beschadiging | B7: Breuk | C7: Breuk | D7: Ongewijzigd
A8: Beschadiging | B8: Deformatie, kritiek | C8: Deformatie, kritiek | D8: Ongewijzigd
A9: Beschadiging | B9: Groeven | C9: Groeven | D9: Ongewijzigd
A10: Beschadiging | B10: Houtrot | C10: Houtrot | D10: Ongewijzigd
A11: Beschadiging | B11: Krassen | C11: Krassen | D11: Ongewijzigd
A12: Beschadiging | B12: Ontgronding | C12: Ontgronding | D12: Ongewijzigd
... A51: Beschadiging | B51: Verruiging | C51: Verruiging | D51: Ongewijzigd
A52: Beschadiging | B52: Vertrapping | D52: Vervallen
A53: Beschadiging | B53: Wildschade | D53: Vervallen
A54: Beschadiging | B54: Aanhechtingsmankement | D54: Vervallen
A55: Beschadiging | B55: Gesteltakken, gescheurd | D55: Vervallen
A56: Beschadiging | C56: Windworp | D56: Toegevoegd
A57: Beschadiging | C57: Omgevallen | D57: Toegevoegd
A58: Beschadiging | C58: Aansluiting, onvoldoende | D58: Toegevoegd
A59: Beschadiging | C59: Erosie | D59: Toegevoegd
A60: Beschadiging | C60: Gaten | D60: Toegevoegd
A61: Bevestiging | B61: Bevestiging, onjuist | C61: Bevestiging, onjuist | D61: Ongewijzigd
A62: Bevestiging | B62: Bevestiging, ontbreekt | C62: Bevestiging, ontbreekt | D62: Ongewijzigd
A63: Bevestiging | B63: Bevestiging, defect | C63: Bevestiging, defect | D63: Ongewijzigd
A64: Codering | B64: Codering, onjuist | C64: Codering, onjuist | D64: Ongewijzigd
A65: Corrosie | B65: Corrosie, uniform | C65: Corrosie, uniform | D65: Ongewijzigd
A66: Corrosie | B66: Putcorrosie | C66: Putcorrosie | D66: Ongewijzigd
A67: Corrosie | B67: Spleetcorrosie | C67: Spleetcorrosie | D67: Ongewijzigd
A68: Corrosie | B68: Wapeningscorrosie | C68: Wapeningscorrosie | D68: Ongewijzigd
A69: Documentatie | B69: Documentatie, onjuist | C69: Documentatie, onjuist | D69: Ongewijzigd
A70: Functionaliteit | B70: Beschermingsgraad, onvoldoende | C70: Beschermingsgraad, onvoldoende | D70: Ongewijzigd
A71: Functionaliteit | B71: Functie, verminderd | C71: Functie, verminderd | D71: Ongewijzigd
A72: Functionaliteit | B72: Functie, afwezig | C72: Functie, afwezig | D72: Ongewijzigd
... A86: Functionaliteit | B86: Vloeistofpeil, onjuist | C86: Vloeistofpeil, onjuist | D86: Ongewijzigd
A87: Functionaliteit | C87: Begroeiing, ongewenst | D87: Toegevoegd
A88: Functionaliteit | C88: Verdwenen | D88: Toegevoegd
A89: Groei, ontwikkeling | B89: Biotoop, afwijkend | C89: Biotoop, afwijkend | D89: Ongewijzigd
A90: Groei, ontwikkeling | B90: Bladkleur, afwijkend | C90: Bladverkleuring | D90: Gewijzigd
A91: Groei, ontwikkeling | B91: Groeistoornis, kritisch | C91: Scheutlengte-ontwikkeling | D91: Gewijzigd
...

Sheet Wijzigingen
A1: Gebrekgroep | B1: Onderdeel | C1: Oud | D1: Nieuw | E1: Mutatie
A2: Beschadiging | B2: Gebrek | C2: Vertrapping | E2: Vervallen
A3: Beschadiging | B3: Gebrek | C3: Wildschade | E3: Vervallen
A4: Beschadiging | B4: Gebrek | C4: Aanhechtingsmankement | E4: Vervallen
A5: Beschadiging | B5: Gebrek | C5: Gesteltakken, gescheurd | E5: Vervallen
A6: Beschadiging | B6: Gebrek | D6: Windworp | E6: Toegevoegd
A7: Beschadiging | B7: Gebrek | D7: Omgevallen | E7: Toegevoegd
A8: Beschadiging | B8: Gebrek | D8: Aansluiting, onvoldoende | E8: Toegevoegd
A9: Beschadiging | B9: Gebrek | D9: Erosie | E9: Toegevoegd
A10: Beschadiging | B10: Gebrek | D10: Gaten | E10: Toegevoegd
A11: Functionaliteit | B11: Gebrek | D11: Begroeiing, ongewenst | E11: Toegevoegd
A12: Functionaliteit | B12: Gebrek | D12: Verdwenen | E12: Toegevoegd
A13: Groei, ontwikkeling | B13: Gebrek | C13: Bladkleur, afwijkend | D13: Bladverkleuring | E13: Gewijzigd
A14: Groei, ontwikkeling | B14: Gebrek | C14: Groeistoornis, kritisch | D14: Scheutlengte-ontwikkeling | E14: Gewijzigd
A15: Groei, ontwikkeling | B15: Gebrek | C15: Snoeiwond, afgrendeling onjuist | D15: Wondreactie | E15: Gewijzigd
A16: Groei, ontwikkeling | B16: Gebrek | C16: Bloeiontwikkeling, onvoldoende | D16: Bloeiontwikkeling | E16: Gewijzigd
A17: Groei, ontwikkeling | B17: Gebrek | C17: Groeihoogte onjuist, kritisch | D17: Stamontwikkeling | E17: Gewijzigd
A18: Groei, ontwikkeling | B18: Gebrek | C18: Groeistoornis, niet kritisch | E18: Vervallen
A19: Groei, ontwikkeling | B19: Gebrek | C19: Groeihoogte onjuist, niet kritisch | E19: Vervallen
A20: Groei, ontwikkeling | B20: Gebrek | C20: Takken laaghangend, niet kritisch | E20: Vervallen
A21: Groei, ontwikkeling | B21: Gebrek | C21: Kroon-stam, verhouding onjuist | E21: Vervallen
A22: Groei, ontwikkeling | B22: Gebrek | C22: Kroon-stam, verhouding afwijkend | E22: Vervallen
A23: Groei, ontwikkeling | B23: Gebrek | C23: Houtige begroeing, onderbroken | E23: Vervallen
A24: Groei, ontwikkeling | B24: Gebrek | C24: Reactiehout | E24: Vervallen
A25: Groei, ontwikkeling | B25: Gebrek | C25: Zuigers, overlast | E25: Vervallen
A26: Groei, ontwikkeling | B26: Gebrek | C26: Wurgwortels | E26: Vervallen
A27: Groei, ontwikkeling | B27: Gebrek | C27: Takken laaghangend, kritisch | E27: Vervallen
A28: Groei, ontwikkeling | B28: Gebrek | C28: Top, dubbel | E28: Vervallen
A29: Groen | B29: Gebrek | C29: Stam, beschadigd | D29: Houtweefselschade | E29: Gewijzigd
A30: Groen | B30: Gebrek | C30: Bedekkingsgraad, onvoldoende | D30: Bedekkingsgraad | E30: Gewijzigd
A31: Groen | B31: Gebrek | C31: Bladontwikkeling, onjuist | D31: Bladontwikkeling | E31: Gewijzigd
A32: Groen | B32: Gebrek | C32: Boomvitaliteit, vermindering | E32: Vervallen
A33: Groen | B33: Gebrek | C33: Kroonontwikkeling, onevenwichtig | E33: Vervallen
A34: Groen | B34: Gebrek | C34: Exotengroei, ongewenst | E34: Vervallen
A35: Groen | B35: Gebrek | C35: Verdroging | E35: Vervallen
A36: Groen | B36: Gebrek | C36: Kroon, beschadigd | E36: Vervallen
A37: Groen | B37: Gebrek | C37: Wortels, beschadigd | E37: Vervallen
A38: Groen | B38: Gebrek | C38: Plakoksel | E38: Vervallen
A39: Groen | B39: Gebrek | D39: Groeiontwikkeling | E39: Toegevoegd
A40: Groen | B40: Gebrek | D40: Afdekking, ongewenst | E40: Toegevoegd
...

Sheet Delta tabel
A1: Delta tabel (gebrek)
A2: Naam | C2: Gebreken
A3: Oud | B3: Nieuw | C3: Oud | D3: Nieuw
A4: Beschadiging | C4: Afbrokkelen | D4: Afbrokkelen
C5: Afdichting, defect | D5: Afdichting, defect
C6: Afschuiving | D6: Afschuiving
C7: Oeverafslag | D7: Oeverafslag
C8: Grasmat, beschadigd | D8: Grasmat, beschadigd
C9: Breuk | D9: Breuk
C10: Deformatie, kritiek | D10: Deformatie, kritiek
C11: Groeven | D11: Groeven
C12: Houtrot | D12: Houtrot
C13: Krassen | D13: Krassen
C14: Ontgronding | D14: Ontgronding
C15: Rafeling | D15: Rafeling
C16: Scheur, niet constructief | D16: Scheur, niet constructief
... C57: Gesteltakken, gescheurd | D57: Erosie
D58: Gaten
A59: Bevestiging | C59: Bevestiging, onjuist | D59: Bevestiging, onjuist
C60: Bevestiging, ontbreekt | D60: Bevestiging, ontbreekt
C61: Bevestiging, defect | D61: Bevestiging, defect
A62: Codering | C62: Codering, onjuist | D62: Codering, onjuist
A63: Conservering
A64: Corrosie | C64: Corrosie, uniform | D64: Corrosie, uniform
C65: Putcorrosie | D65: Putcorrosie
C66: Spleetcorrosie | D66: Spleetcorrosie
C67: Wapeningscorrosie | D67: Wapeningscorrosie
A68: Documentatie | C68: Documentatie, onjuist | D68: Documentatie, onjuist
A69: Functionaliteit | C69: Beschermingsgraad, onvoldoende | D69: Beschermingsgraad, onvoldoende
C70: Functie, verminderd | D70: Functie, verminderd
C71: Functie, afwezig | D71: Functie, afwezig
C72: Servicetermijn, ten einde | D72: Servicetermijn, ten einde
C73: Instelling, foutief | D73: Instelling, foutief
C74: Kortsluitvastheid, onvoldoende | D74: Kortsluitvastheid, onvoldoende
C75: Markering, onjuist | D75: Markering, onjuist
C76: Onderdeel, ontbreekt | D76: Onderdeel, ontbreekt
C77: Diepte, onvoldoende | D77: Diepte, onvoldoende
C78: Smering, onvoldoende | D78: Smering, onvoldoende
C79: Trilling, overmatig | D79: Trilling, overmatig
C80: Warmte-ontwikkeling, overmatig | D80: Warmte-ontwikkeling, overmatig
...
